2025-05-08 18:18:41,393 - __main__ - INFO - Loading data files...
2025-05-08 18:18:41,393 - __main__ - INFO - Computing sentiment statistics...
2025-05-08 18:18:41,393 - __main__ - INFO - Generating visualizations...
2025-05-08 18:18:41,721 - __main__ - WARNING - No data available for sentiment distribution plot
2025-05-08 18:18:42,008 - __main__ - INFO - Saved sentiment by content length plot to: data/sentiment/visualizations/sentiment_by_length.png
2025-05-08 18:18:42,145 - __main__ - INFO - Saved sentiment by engagement plot to: data/sentiment/visualizations/sentiment_by_engagement.png
2025-05-08 18:18:42,145 - __main__ - INFO - Generating top words visualizations...
2025-05-08 18:18:42,145 - __main__ - INFO - Generating wordclouds...
2025-05-08 18:18:42,302 - __main__ - INFO - Saved sentiment over time plot to: data/sentiment/visualizations/sentiment_over_time.png
2025-05-08 18:18:42,302 - __main__ - INFO - Generating HTML report...
2025-05-08 18:18:42,302 - __main__ - INFO - Generated HTML report at: data/sentiment/sentiment_report.html
2025-05-08 18:18:42,302 - __main__ - INFO - Saving analyzed data...
2025-05-08 18:18:42,303 - __main__ - INFO - Sentiment analysis complete!
2025-05-08 18:18:42,303 - __main__ - INFO - All outputs saved to: data/sentiment
2025-05-08 18:18:42,303 - __main__ - INFO - Analysis complete!
2025-05-08 18:18:42,303 - __main__ - INFO - HTML report available at: data/sentiment/sentiment_report.html
2025-05-08 18:35:19,262 - __main__ - INFO - Loading data files...
2025-05-08 18:35:19,263 - __main__ - INFO - Loading Reddit posts from: data/raw/reddit_posts_20250506_180725.csv
2025-05-08 18:35:19,266 - __main__ - INFO - Loaded 0 Reddit posts
2025-05-08 18:35:19,266 - __main__ - INFO - Loading Reddit comments from: data/raw/reddit_comments_20250506_180008.csv
2025-05-08 18:35:19,267 - __main__ - INFO - Loaded 6 Reddit comments
2025-05-08 18:35:19,267 - __main__ - INFO - Loading Twitter data from: twitter_data/the_climate_change_twitter_dataset.csv
2025-05-08 18:35:31,556 - __main__ - INFO - Loaded 15789411 Twitter posts
2025-05-08 18:35:31,578 - __main__ - ERROR - Twitter dataset must contain a 'cleaned_text' or 'text' column
2025-05-08 18:35:31,578 - __main__ - ERROR - Error during sentiment analysis: Twitter dataset must contain a 'cleaned_text' or 'text' column
Traceback (most recent call last):
  File "/Users/blueberry/Library/CloudStorage/OneDrive-UniversitätZürichUZH/Studium/FS25/SoComp/SC_RP/rp_implementation/SoComp-FS25/sentiment_analyzer.py", line 1163, in main
    outputs = analyzer.run_complete_analysis(
        reddit_posts_file=args.reddit_posts,
        reddit_comments_file=args.reddit_comments,
        twitter_file=args.twitter
    )
  File "/Users/blueberry/Library/CloudStorage/OneDrive-UniversitätZürichUZH/Studium/FS25/SoComp/SC_RP/rp_implementation/SoComp-FS25/sentiment_analyzer.py", line 1017, in run_complete_analysis
    data = self.load_data(reddit_posts_file, reddit_comments_file, twitter_file)
  File "/Users/blueberry/Library/CloudStorage/OneDrive-UniversitätZürichUZH/Studium/FS25/SoComp/SC_RP/rp_implementation/SoComp-FS25/sentiment_analyzer.py", line 130, in load_data
    raise ValueError("Twitter dataset must contain a 'cleaned_text' or 'text' column")
ValueError: Twitter dataset must contain a 'cleaned_text' or 'text' column
2025-05-08 18:42:45,005 - __main__ - INFO - Loading data files...
2025-05-08 18:42:45,005 - __main__ - INFO - Loading Reddit posts from: data/raw/reddit_posts_20250506_180725.csv
2025-05-08 18:42:45,006 - __main__ - INFO - Loaded 0 Reddit posts
2025-05-08 18:42:45,006 - __main__ - INFO - Loading Reddit comments from: data/raw/reddit_comments_20250506_180008.csv
2025-05-08 18:42:45,007 - __main__ - INFO - Loaded 6 Reddit comments
2025-05-08 18:42:45,007 - __main__ - INFO - Loading Twitter data from: twitter_data/the_climate_change_twitter_dataset.csv
2025-05-08 18:42:57,401 - __main__ - INFO - Loaded 15789411 Twitter posts
2025-05-08 18:42:57,424 - __main__ - ERROR - Twitter dataset must contain a 'cleaned_text' or 'text' column
2025-05-08 18:42:57,424 - __main__ - ERROR - Error during sentiment analysis: Twitter dataset must contain a 'cleaned_text' or 'text' column
Traceback (most recent call last):
  File "/Users/blueberry/Library/CloudStorage/OneDrive-UniversitätZürichUZH/Studium/FS25/SoComp/SC_RP/rp_implementation/SoComp-FS25/sentiment_analyzer.py", line 1163, in main
    outputs = analyzer.run_complete_analysis(
        reddit_posts_file=args.reddit_posts,
        reddit_comments_file=args.reddit_comments,
        twitter_file=args.twitter
    )
  File "/Users/blueberry/Library/CloudStorage/OneDrive-UniversitätZürichUZH/Studium/FS25/SoComp/SC_RP/rp_implementation/SoComp-FS25/sentiment_analyzer.py", line 1017, in run_complete_analysis
    data = self.load_data(reddit_posts_file, reddit_comments_file, twitter_file)
  File "/Users/blueberry/Library/CloudStorage/OneDrive-UniversitätZürichUZH/Studium/FS25/SoComp/SC_RP/rp_implementation/SoComp-FS25/sentiment_analyzer.py", line 130, in load_data
    raise ValueError("Twitter dataset must contain a 'cleaned_text' or 'text' column")
ValueError: Twitter dataset must contain a 'cleaned_text' or 'text' column
2025-05-08 18:59:24,772 - __main__ - INFO - Loading data files...
2025-05-08 18:59:24,773 - __main__ - INFO - Loading Reddit posts from: data/raw/reddit_posts_20250506_180725.csv
2025-05-08 18:59:24,775 - __main__ - INFO - Loaded 0 Reddit posts
2025-05-08 18:59:24,775 - __main__ - INFO - Loading Reddit comments from: data/raw/reddit_comments_20250506_180008.csv
2025-05-08 18:59:24,776 - __main__ - INFO - Loaded 6 Reddit comments
2025-05-08 18:59:24,776 - __main__ - INFO - Loading Twitter data from: twitter_data/twitter_sentiment_data.csv
2025-05-08 18:59:24,826 - __main__ - INFO - Loaded 43943 Twitter posts
2025-05-08 18:59:24,826 - __main__ - WARNING - Twitter dataset does not contain a 'topic' column. Some analyses may be limited.
2025-05-08 18:59:24,826 - __main__ - INFO - Analyzing sentiment for reddit_comments...
2025-05-08 18:59:24,826 - __main__ - INFO - Applying sentiment analysis to 6 items...
2025-05-08 18:59:24,845 - __main__ - INFO - Sentiment analysis complete
2025-05-08 18:59:24,846 - __main__ - INFO - Analyzing sentiment for twitter...
2025-05-08 18:59:24,846 - __main__ - INFO - Applying sentiment analysis to 43943 items...
2025-05-08 18:59:24,847 - __main__ - ERROR - Error during sentiment analysis: 'text'
Traceback (most recent call last):
  File "/Users/blueberry/Library/CloudStorage/OneDrive-UniversitätZürichUZH/Studium/FS25/SoComp/SC_RP/rp_implementation/SoComp-FS25/myenv/lib/python3.13/site-packages/pandas/core/indexes/base.py", line 3805, in get_loc
    return self._engine.get_loc(casted_key)
           ~~~~~~~~~~~~~~~~~~~~^^^^^^^^^^^^
  File "index.pyx", line 167, in pandas._libs.index.IndexEngine.get_loc
  File "index.pyx", line 196, in pandas._libs.index.IndexEngine.get_loc
  File "pandas/_libs/hashtable_class_helper.pxi", line 7081, in pandas._libs.hashtable.PyObjectHashTable.get_item
  File "pandas/_libs/hashtable_class_helper.pxi", line 7089, in pandas._libs.hashtable.PyObjectHashTable.get_item
KeyError: 'text'

The above exception was the direct cause of the following exception:

Traceback (most recent call last):
  File "/Users/blueberry/Library/CloudStorage/OneDrive-UniversitätZürichUZH/Studium/FS25/SoComp/SC_RP/rp_implementation/SoComp-FS25/sentiment_analyzer.py", line 1154, in main
    outputs = analyzer.run_complete_analysis(
        reddit_posts_file=args.reddit_posts,
        reddit_comments_file=args.reddit_comments,
        twitter_file=args.twitter
    )
  File "/Users/blueberry/Library/CloudStorage/OneDrive-UniversitätZürichUZH/Studium/FS25/SoComp/SC_RP/rp_implementation/SoComp-FS25/sentiment_analyzer.py", line 1017, in run_complete_analysis
    analyzed_data[key] = self.apply_sentiment_analysis(df, text_column)
                         ~~~~~~~~~~~~~~~~~~~~~~~~~~~~~^^^^^^^^^^^^^^^^^
  File "/Users/blueberry/Library/CloudStorage/OneDrive-UniversitätZürichUZH/Studium/FS25/SoComp/SC_RP/rp_implementation/SoComp-FS25/sentiment_analyzer.py", line 176, in apply_sentiment_analysis
    sentiments = batch[text_column].apply(self.analyze_sentiment)
                 ~~~~~^^^^^^^^^^^^^
  File "/Users/blueberry/Library/CloudStorage/OneDrive-UniversitätZürichUZH/Studium/FS25/SoComp/SC_RP/rp_implementation/SoComp-FS25/myenv/lib/python3.13/site-packages/pandas/core/frame.py", line 4102, in __getitem__
    indexer = self.columns.get_loc(key)
  File "/Users/blueberry/Library/CloudStorage/OneDrive-UniversitätZürichUZH/Studium/FS25/SoComp/SC_RP/rp_implementation/SoComp-FS25/myenv/lib/python3.13/site-packages/pandas/core/indexes/base.py", line 3812, in get_loc
    raise KeyError(key) from err
KeyError: 'text'
2025-05-08 19:01:33,427 - __main__ - INFO - Loading data files...
2025-05-08 19:01:33,428 - __main__ - INFO - Loading Reddit posts from: data/raw/reddit_posts_20250506_180725.csv
2025-05-08 19:01:33,429 - __main__ - INFO - Loaded 0 Reddit posts
2025-05-08 19:01:33,429 - __main__ - INFO - Loading Reddit comments from: data/raw/reddit_comments_20250506_180008.csv
2025-05-08 19:01:33,430 - __main__ - INFO - Loaded 6 Reddit comments
2025-05-08 19:01:33,430 - __main__ - INFO - Loading Twitter data from: twitter_data/twitter_sentiment_data.csv
2025-05-08 19:01:33,477 - __main__ - INFO - Loaded 43943 Twitter posts
2025-05-08 19:01:33,477 - __main__ - WARNING - Twitter dataset does not contain a 'topic' column. Some analyses may be limited.
2025-05-08 19:01:33,477 - __main__ - INFO - Analyzing sentiment for reddit_comments...
2025-05-08 19:01:33,477 - __main__ - INFO - Applying sentiment analysis to 6 items...
2025-05-08 19:01:33,493 - __main__ - INFO - Sentiment analysis complete
2025-05-08 19:01:33,493 - __main__ - INFO - Analyzing sentiment for twitter...
2025-05-08 19:01:33,493 - __main__ - INFO - Applying sentiment analysis to 43943 items...
2025-05-08 19:01:36,706 - __main__ - INFO - Sentiment analysis complete
2025-05-08 19:01:36,706 - __main__ - INFO - Computing sentiment statistics...
2025-05-08 19:01:36,706 - __main__ - ERROR - Error during sentiment analysis: 'sentiment_category'
Traceback (most recent call last):
  File "/Users/blueberry/Library/CloudStorage/OneDrive-UniversitätZürichUZH/Studium/FS25/SoComp/SC_RP/rp_implementation/SoComp-FS25/myenv/lib/python3.13/site-packages/pandas/core/indexes/base.py", line 3805, in get_loc
    return self._engine.get_loc(casted_key)
           ~~~~~~~~~~~~~~~~~~~~^^^^^^^^^^^^
  File "index.pyx", line 167, in pandas._libs.index.IndexEngine.get_loc
  File "index.pyx", line 196, in pandas._libs.index.IndexEngine.get_loc
  File "pandas/_libs/hashtable_class_helper.pxi", line 7081, in pandas._libs.hashtable.PyObjectHashTable.get_item
  File "pandas/_libs/hashtable_class_helper.pxi", line 7089, in pandas._libs.hashtable.PyObjectHashTable.get_item
KeyError: 'sentiment_category'

The above exception was the direct cause of the following exception:

Traceback (most recent call last):
  File "/Users/blueberry/Library/CloudStorage/OneDrive-UniversitätZürichUZH/Studium/FS25/SoComp/SC_RP/rp_implementation/SoComp-FS25/sentiment_analyzer.py", line 1157, in main
    outputs = analyzer.run_complete_analysis(
        reddit_posts_file=args.reddit_posts,
        reddit_comments_file=args.reddit_comments,
        twitter_file=args.twitter
    )
  File "/Users/blueberry/Library/CloudStorage/OneDrive-UniversitätZürichUZH/Studium/FS25/SoComp/SC_RP/rp_implementation/SoComp-FS25/sentiment_analyzer.py", line 1032, in run_complete_analysis
    sentiment_stats = self.compute_sentiment_stats(analyzed_data)
  File "/Users/blueberry/Library/CloudStorage/OneDrive-UniversitätZürichUZH/Studium/FS25/SoComp/SC_RP/rp_implementation/SoComp-FS25/sentiment_analyzer.py", line 238, in compute_sentiment_stats
    sentiment_counts = df['sentiment_category'].value_counts(normalize=True).to_dict()
                       ~~^^^^^^^^^^^^^^^^^^^^^^
  File "/Users/blueberry/Library/CloudStorage/OneDrive-UniversitätZürichUZH/Studium/FS25/SoComp/SC_RP/rp_implementation/SoComp-FS25/myenv/lib/python3.13/site-packages/pandas/core/frame.py", line 4102, in __getitem__
    indexer = self.columns.get_loc(key)
  File "/Users/blueberry/Library/CloudStorage/OneDrive-UniversitätZürichUZH/Studium/FS25/SoComp/SC_RP/rp_implementation/SoComp-FS25/myenv/lib/python3.13/site-packages/pandas/core/indexes/base.py", line 3812, in get_loc
    raise KeyError(key) from err
KeyError: 'sentiment_category'
2025-05-08 19:15:14,333 - __main__ - INFO - Loading data files...
2025-05-08 19:15:14,334 - __main__ - INFO - Loading Reddit posts from: data/raw/reddit_posts_20250506_180725.csv
2025-05-08 19:15:14,335 - __main__ - INFO - Loaded 0 Reddit posts
2025-05-08 19:15:14,336 - __main__ - INFO - Loading Reddit comments from: data/raw/reddit_comments_20250506_180008.csv
2025-05-08 19:15:14,336 - __main__ - INFO - Loaded 6 Reddit comments
2025-05-08 19:15:14,336 - __main__ - INFO - Loading Twitter data from: twitter_data/twitter_sentiment_data.csv
2025-05-08 19:15:14,383 - __main__ - INFO - Loaded 43943 Twitter posts
2025-05-08 19:15:14,383 - __main__ - WARNING - Twitter dataset does not contain a 'topic' column. Some analyses may be limited.
2025-05-08 19:15:14,383 - __main__ - INFO - Analyzing sentiment for reddit_comments...
2025-05-08 19:15:14,383 - __main__ - INFO - Applying sentiment analysis to 6 items...
2025-05-08 19:15:14,405 - __main__ - INFO - Sentiment analysis complete
2025-05-08 19:15:14,405 - __main__ - INFO - Analyzing sentiment for twitter...
2025-05-08 19:15:14,405 - __main__ - INFO - Applying sentiment analysis to 43943 items...
2025-05-08 19:15:17,533 - __main__ - INFO - Sentiment analysis complete
2025-05-08 19:15:17,533 - __main__ - INFO - Computing sentiment statistics...
2025-05-08 19:15:17,533 - __main__ - ERROR - Error during sentiment analysis: 'sentiment_category'
Traceback (most recent call last):
  File "/Users/blueberry/Library/CloudStorage/OneDrive-UniversitätZürichUZH/Studium/FS25/SoComp/SC_RP/rp_implementation/SoComp-FS25/myenv/lib/python3.13/site-packages/pandas/core/indexes/base.py", line 3805, in get_loc
    return self._engine.get_loc(casted_key)
           ~~~~~~~~~~~~~~~~~~~~^^^^^^^^^^^^
  File "index.pyx", line 167, in pandas._libs.index.IndexEngine.get_loc
  File "index.pyx", line 196, in pandas._libs.index.IndexEngine.get_loc
  File "pandas/_libs/hashtable_class_helper.pxi", line 7081, in pandas._libs.hashtable.PyObjectHashTable.get_item
  File "pandas/_libs/hashtable_class_helper.pxi", line 7089, in pandas._libs.hashtable.PyObjectHashTable.get_item
KeyError: 'sentiment_category'

The above exception was the direct cause of the following exception:

Traceback (most recent call last):
  File "/Users/blueberry/Library/CloudStorage/OneDrive-UniversitätZürichUZH/Studium/FS25/SoComp/SC_RP/rp_implementation/SoComp-FS25/sentiment_analyzer.py", line 1158, in main
    outputs = analyzer.run_complete_analysis(
        reddit_posts_file=args.reddit_posts,
        reddit_comments_file=args.reddit_comments,
        twitter_file=args.twitter
    )
  File "/Users/blueberry/Library/CloudStorage/OneDrive-UniversitätZürichUZH/Studium/FS25/SoComp/SC_RP/rp_implementation/SoComp-FS25/sentiment_analyzer.py", line 1033, in run_complete_analysis
    sentiment_stats = self.compute_sentiment_stats(analyzed_data)
  File "/Users/blueberry/Library/CloudStorage/OneDrive-UniversitätZürichUZH/Studium/FS25/SoComp/SC_RP/rp_implementation/SoComp-FS25/sentiment_analyzer.py", line 239, in compute_sentiment_stats
    sentiment_counts = df['sentiment_category'].value_counts(normalize=True).to_dict()
                       ~~^^^^^^^^^^^^^^^^^^^^^^
  File "/Users/blueberry/Library/CloudStorage/OneDrive-UniversitätZürichUZH/Studium/FS25/SoComp/SC_RP/rp_implementation/SoComp-FS25/myenv/lib/python3.13/site-packages/pandas/core/frame.py", line 4102, in __getitem__
    indexer = self.columns.get_loc(key)
  File "/Users/blueberry/Library/CloudStorage/OneDrive-UniversitätZürichUZH/Studium/FS25/SoComp/SC_RP/rp_implementation/SoComp-FS25/myenv/lib/python3.13/site-packages/pandas/core/indexes/base.py", line 3812, in get_loc
    raise KeyError(key) from err
KeyError: 'sentiment_category'
2025-05-08 19:17:57,381 - __main__ - INFO - Loading data files...
2025-05-08 19:17:57,381 - __main__ - INFO - Loading Reddit posts from: data/raw/reddit_posts_20250506_180725.csv
2025-05-08 19:17:57,383 - __main__ - INFO - Loaded 0 Reddit posts
2025-05-08 19:17:57,383 - __main__ - INFO - Loading Reddit comments from: data/raw/reddit_comments_20250506_180008.csv
2025-05-08 19:17:57,384 - __main__ - INFO - Loaded 6 Reddit comments
2025-05-08 19:17:57,384 - __main__ - INFO - Loading Twitter data from: twitter_data/twitter_sentiment_data.csv
2025-05-08 19:17:57,433 - __main__ - INFO - Loaded 43943 Twitter posts
2025-05-08 19:17:57,433 - __main__ - WARNING - Twitter dataset does not contain a 'topic' column. Some analyses may be limited.
2025-05-08 19:17:57,433 - __main__ - INFO - Analyzing sentiment for reddit_comments...
2025-05-08 19:17:57,433 - __main__ - INFO - Applying sentiment analysis to 6 items...
2025-05-08 19:17:57,454 - __main__ - INFO - Sentiment analysis complete
2025-05-08 19:17:57,454 - __main__ - INFO - Analyzing sentiment for twitter...
2025-05-08 19:17:57,454 - __main__ - INFO - Applying sentiment analysis to 43943 items...
2025-05-08 19:18:00,654 - __main__ - INFO - Sentiment analysis complete
2025-05-08 19:18:00,654 - __main__ - INFO - Computing sentiment statistics...
2025-05-08 19:18:00,654 - __main__ - ERROR - Error during sentiment analysis: 'sentiment_category'
Traceback (most recent call last):
  File "/Users/blueberry/Library/CloudStorage/OneDrive-UniversitätZürichUZH/Studium/FS25/SoComp/SC_RP/rp_implementation/SoComp-FS25/myenv/lib/python3.13/site-packages/pandas/core/indexes/base.py", line 3805, in get_loc
    return self._engine.get_loc(casted_key)
           ~~~~~~~~~~~~~~~~~~~~^^^^^^^^^^^^
  File "index.pyx", line 167, in pandas._libs.index.IndexEngine.get_loc
  File "index.pyx", line 196, in pandas._libs.index.IndexEngine.get_loc
  File "pandas/_libs/hashtable_class_helper.pxi", line 7081, in pandas._libs.hashtable.PyObjectHashTable.get_item
  File "pandas/_libs/hashtable_class_helper.pxi", line 7089, in pandas._libs.hashtable.PyObjectHashTable.get_item
KeyError: 'sentiment_category'

The above exception was the direct cause of the following exception:

Traceback (most recent call last):
  File "/Users/blueberry/Library/CloudStorage/OneDrive-UniversitätZürichUZH/Studium/FS25/SoComp/SC_RP/rp_implementation/SoComp-FS25/sentiment_analyzer.py", line 1168, in main
    outputs = analyzer.run_complete_analysis(
        reddit_posts_file=args.reddit_posts,
        reddit_comments_file=args.reddit_comments,
        twitter_file=args.twitter
    )
  File "/Users/blueberry/Library/CloudStorage/OneDrive-UniversitätZürichUZH/Studium/FS25/SoComp/SC_RP/rp_implementation/SoComp-FS25/sentiment_analyzer.py", line 1043, in run_complete_analysis
    sentiment_stats = self.compute_sentiment_stats(analyzed_data)
  File "/Users/blueberry/Library/CloudStorage/OneDrive-UniversitätZürichUZH/Studium/FS25/SoComp/SC_RP/rp_implementation/SoComp-FS25/sentiment_analyzer.py", line 249, in compute_sentiment_stats
    sentiment_counts = df['sentiment_category'].value_counts(normalize=True).to_dict()
                       ~~^^^^^^^^^^^^^^^^^^^^^^
  File "/Users/blueberry/Library/CloudStorage/OneDrive-UniversitätZürichUZH/Studium/FS25/SoComp/SC_RP/rp_implementation/SoComp-FS25/myenv/lib/python3.13/site-packages/pandas/core/frame.py", line 4102, in __getitem__
    indexer = self.columns.get_loc(key)
  File "/Users/blueberry/Library/CloudStorage/OneDrive-UniversitätZürichUZH/Studium/FS25/SoComp/SC_RP/rp_implementation/SoComp-FS25/myenv/lib/python3.13/site-packages/pandas/core/indexes/base.py", line 3812, in get_loc
    raise KeyError(key) from err
KeyError: 'sentiment_category'
2025-05-08 19:21:34,402 - __main__ - INFO - Loading data files...
2025-05-08 19:21:34,402 - __main__ - INFO - Loading Reddit posts from: data/raw/reddit_posts_20250506_180725.csv
2025-05-08 19:21:34,404 - __main__ - INFO - Loaded 0 Reddit posts
2025-05-08 19:21:34,404 - __main__ - INFO - Loading Reddit comments from: data/raw/reddit_comments_20250506_180008.csv
2025-05-08 19:21:34,405 - __main__ - INFO - Loaded 6 Reddit comments
2025-05-08 19:21:34,405 - __main__ - INFO - Loading Twitter data from: twitter_data/twitter_sentiment_data.csv
2025-05-08 19:21:34,454 - __main__ - INFO - Loaded 43943 Twitter posts
2025-05-08 19:21:34,455 - __main__ - INFO - Analyzing sentiment for reddit_comments...
2025-05-08 19:21:34,455 - __main__ - INFO - Applying sentiment analysis to 6 items...
2025-05-08 19:21:34,475 - __main__ - INFO - Sentiment analysis complete
2025-05-08 19:21:34,475 - __main__ - INFO - Analyzing sentiment for twitter...
2025-05-08 19:21:34,475 - __main__ - INFO - Applying sentiment analysis to 43943 items...
2025-05-08 19:21:37,653 - __main__ - INFO - Sentiment analysis complete
2025-05-08 19:21:37,654 - __main__ - INFO - Computing sentiment statistics...
2025-05-08 19:21:37,654 - __main__ - ERROR - Error during sentiment analysis: 'sentiment_category'
Traceback (most recent call last):
  File "/Users/blueberry/Library/CloudStorage/OneDrive-UniversitätZürichUZH/Studium/FS25/SoComp/SC_RP/rp_implementation/SoComp-FS25/myenv/lib/python3.13/site-packages/pandas/core/indexes/base.py", line 3805, in get_loc
    return self._engine.get_loc(casted_key)
           ~~~~~~~~~~~~~~~~~~~~^^^^^^^^^^^^
  File "index.pyx", line 167, in pandas._libs.index.IndexEngine.get_loc
  File "index.pyx", line 196, in pandas._libs.index.IndexEngine.get_loc
  File "pandas/_libs/hashtable_class_helper.pxi", line 7081, in pandas._libs.hashtable.PyObjectHashTable.get_item
  File "pandas/_libs/hashtable_class_helper.pxi", line 7089, in pandas._libs.hashtable.PyObjectHashTable.get_item
KeyError: 'sentiment_category'

The above exception was the direct cause of the following exception:

Traceback (most recent call last):
  File "/Users/blueberry/Library/CloudStorage/OneDrive-UniversitätZürichUZH/Studium/FS25/SoComp/SC_RP/rp_implementation/SoComp-FS25/sentiment_analyzer.py", line 1166, in main
    outputs = analyzer.run_complete_analysis(
        reddit_posts_file=args.reddit_posts,
        reddit_comments_file=args.reddit_comments,
        twitter_file=args.twitter
    )
  File "/Users/blueberry/Library/CloudStorage/OneDrive-UniversitätZürichUZH/Studium/FS25/SoComp/SC_RP/rp_implementation/SoComp-FS25/sentiment_analyzer.py", line 1041, in run_complete_analysis
    sentiment_stats = self.compute_sentiment_stats(analyzed_data)
  File "/Users/blueberry/Library/CloudStorage/OneDrive-UniversitätZürichUZH/Studium/FS25/SoComp/SC_RP/rp_implementation/SoComp-FS25/sentiment_analyzer.py", line 247, in compute_sentiment_stats
    sentiment_counts = df['sentiment_category'].value_counts(normalize=True).to_dict()
                       ~~^^^^^^^^^^^^^^^^^^^^^^
  File "/Users/blueberry/Library/CloudStorage/OneDrive-UniversitätZürichUZH/Studium/FS25/SoComp/SC_RP/rp_implementation/SoComp-FS25/myenv/lib/python3.13/site-packages/pandas/core/frame.py", line 4102, in __getitem__
    indexer = self.columns.get_loc(key)
  File "/Users/blueberry/Library/CloudStorage/OneDrive-UniversitätZürichUZH/Studium/FS25/SoComp/SC_RP/rp_implementation/SoComp-FS25/myenv/lib/python3.13/site-packages/pandas/core/indexes/base.py", line 3812, in get_loc
    raise KeyError(key) from err
KeyError: 'sentiment_category'
2025-05-08 19:24:47,891 - __main__ - INFO - Loading data files...
2025-05-08 19:24:47,894 - __main__ - INFO - Loading Reddit posts from: data/raw/reddit_posts_20250506_180725.csv
2025-05-08 19:24:47,894 - __main__ - INFO - Loaded 0 Reddit posts
2025-05-08 19:24:47,895 - __main__ - INFO - Loading Reddit comments from: data/raw/reddit_comments_20250506_180008.csv
2025-05-08 19:24:47,895 - __main__ - INFO - Loaded 6 Reddit comments
2025-05-08 19:24:47,895 - __main__ - INFO - Loading Twitter data from: twitter_data/twitter_sentiment_data.csv
2025-05-08 19:24:47,940 - __main__ - INFO - Loaded 43943 Twitter posts
2025-05-08 19:24:47,940 - __main__ - INFO - Analyzing sentiment for reddit_comments...
2025-05-08 19:24:47,941 - __main__ - INFO - Applying sentiment analysis to 6 items...
2025-05-08 19:24:47,952 - __main__ - ERROR - Error during sentiment analysis: 'dict' object has no attribute 'head'
Traceback (most recent call last):
  File "/Users/blueberry/Library/CloudStorage/OneDrive-UniversitätZürichUZH/Studium/FS25/SoComp/SC_RP/rp_implementation/SoComp-FS25/sentiment_analyzer.py", line 1169, in main
    outputs = analyzer.run_complete_analysis(
        reddit_posts_file=args.reddit_posts,
        reddit_comments_file=args.reddit_comments,
        twitter_file=args.twitter
    )
  File "/Users/blueberry/Library/CloudStorage/OneDrive-UniversitätZürichUZH/Studium/FS25/SoComp/SC_RP/rp_implementation/SoComp-FS25/sentiment_analyzer.py", line 1032, in run_complete_analysis
    analyzed_data[key] = self.apply_sentiment_analysis(df, text_column)
                         ~~~~~~~~~~~~~~~~~~~~~~~~~~~~~^^^^^^^^^^^^^^^^^
  File "/Users/blueberry/Library/CloudStorage/OneDrive-UniversitätZürichUZH/Studium/FS25/SoComp/SC_RP/rp_implementation/SoComp-FS25/sentiment_analyzer.py", line 187, in apply_sentiment_analysis
    sentiments = batch[text_column].apply(self.analyze_sentiment)
  File "/Users/blueberry/Library/CloudStorage/OneDrive-UniversitätZürichUZH/Studium/FS25/SoComp/SC_RP/rp_implementation/SoComp-FS25/myenv/lib/python3.13/site-packages/pandas/core/series.py", line 4924, in apply
    ).apply()
      ~~~~~^^
  File "/Users/blueberry/Library/CloudStorage/OneDrive-UniversitätZürichUZH/Studium/FS25/SoComp/SC_RP/rp_implementation/SoComp-FS25/myenv/lib/python3.13/site-packages/pandas/core/apply.py", line 1427, in apply
    return self.apply_standard()
           ~~~~~~~~~~~~~~~~~~~^^
  File "/Users/blueberry/Library/CloudStorage/OneDrive-UniversitätZürichUZH/Studium/FS25/SoComp/SC_RP/rp_implementation/SoComp-FS25/myenv/lib/python3.13/site-packages/pandas/core/apply.py", line 1507, in apply_standard
    mapped = obj._map_values(
        mapper=curried, na_action=action, convert=self.convert_dtype
    )
  File "/Users/blueberry/Library/CloudStorage/OneDrive-UniversitätZürichUZH/Studium/FS25/SoComp/SC_RP/rp_implementation/SoComp-FS25/myenv/lib/python3.13/site-packages/pandas/core/base.py", line 921, in _map_values
    return algorithms.map_array(arr, mapper, na_action=na_action, convert=convert)
           ~~~~~~~~~~~~~~~~~~~~^^^^^^^^^^^^^^^^^^^^^^^^^^^^^^^^^^^^^^^^^^^^^^^^^^^
  File "/Users/blueberry/Library/CloudStorage/OneDrive-UniversitätZürichUZH/Studium/FS25/SoComp/SC_RP/rp_implementation/SoComp-FS25/myenv/lib/python3.13/site-packages/pandas/core/algorithms.py", line 1743, in map_array
    return lib.map_infer(values, mapper, convert=convert)
           ~~~~~~~~~~~~~^^^^^^^^^^^^^^^^^^^^^^^^^^^^^^^^^
  File "lib.pyx", line 2972, in pandas._libs.lib.map_infer
  File "/Users/blueberry/Library/CloudStorage/OneDrive-UniversitätZürichUZH/Studium/FS25/SoComp/SC_RP/rp_implementation/SoComp-FS25/sentiment_analyzer.py", line 158, in analyze_sentiment
    logger.debug(f"Sentiment analysis output: {sentiment_scores.head()}")
                                               ^^^^^^^^^^^^^^^^^^^^^
AttributeError: 'dict' object has no attribute 'head'
2025-05-08 19:25:40,300 - __main__ - INFO - Loading data files...
2025-05-08 19:25:40,300 - __main__ - INFO - Loading Reddit posts from: data/raw/reddit_posts_20250506_180725.csv
2025-05-08 19:25:40,301 - __main__ - INFO - Loaded 0 Reddit posts
2025-05-08 19:25:40,302 - __main__ - INFO - Loading Reddit comments from: data/raw/reddit_comments_20250506_180008.csv
2025-05-08 19:25:40,302 - __main__ - INFO - Loaded 6 Reddit comments
2025-05-08 19:25:40,303 - __main__ - INFO - Loading Twitter data from: twitter_data/twitter_sentiment_data.csv
2025-05-08 19:25:40,355 - __main__ - INFO - Loaded 43943 Twitter posts
2025-05-08 19:25:40,355 - __main__ - INFO - Analyzing sentiment for reddit_comments...
2025-05-08 19:25:40,355 - __main__ - INFO - Applying sentiment analysis to 6 items...
2025-05-08 19:25:40,375 - __main__ - INFO - Sentiment analysis complete
2025-05-08 19:25:40,375 - __main__ - INFO - Analyzing sentiment for twitter...
2025-05-08 19:25:40,375 - __main__ - INFO - Applying sentiment analysis to 43943 items...
2025-05-08 19:25:43,629 - __main__ - INFO - Sentiment analysis complete
2025-05-08 19:25:43,629 - __main__ - INFO - Computing sentiment statistics...
2025-05-08 19:25:43,629 - __main__ - ERROR - Error during sentiment analysis: 'sentiment_category'
Traceback (most recent call last):
  File "/Users/blueberry/Library/CloudStorage/OneDrive-UniversitätZürichUZH/Studium/FS25/SoComp/SC_RP/rp_implementation/SoComp-FS25/myenv/lib/python3.13/site-packages/pandas/core/indexes/base.py", line 3805, in get_loc
    return self._engine.get_loc(casted_key)
           ~~~~~~~~~~~~~~~~~~~~^^^^^^^^^^^^
  File "index.pyx", line 167, in pandas._libs.index.IndexEngine.get_loc
  File "index.pyx", line 196, in pandas._libs.index.IndexEngine.get_loc
  File "pandas/_libs/hashtable_class_helper.pxi", line 7081, in pandas._libs.hashtable.PyObjectHashTable.get_item
  File "pandas/_libs/hashtable_class_helper.pxi", line 7089, in pandas._libs.hashtable.PyObjectHashTable.get_item
KeyError: 'sentiment_category'

The above exception was the direct cause of the following exception:

Traceback (most recent call last):
  File "/Users/blueberry/Library/CloudStorage/OneDrive-UniversitätZürichUZH/Studium/FS25/SoComp/SC_RP/rp_implementation/SoComp-FS25/sentiment_analyzer.py", line 1169, in main
    outputs = analyzer.run_complete_analysis(
        reddit_posts_file=args.reddit_posts,
        reddit_comments_file=args.reddit_comments,
        twitter_file=args.twitter
    )
  File "/Users/blueberry/Library/CloudStorage/OneDrive-UniversitätZürichUZH/Studium/FS25/SoComp/SC_RP/rp_implementation/SoComp-FS25/sentiment_analyzer.py", line 1044, in run_complete_analysis
    sentiment_stats = self.compute_sentiment_stats(analyzed_data)
  File "/Users/blueberry/Library/CloudStorage/OneDrive-UniversitätZürichUZH/Studium/FS25/SoComp/SC_RP/rp_implementation/SoComp-FS25/sentiment_analyzer.py", line 250, in compute_sentiment_stats
    sentiment_counts = df['sentiment_category'].value_counts(normalize=True).to_dict()
                       ~~^^^^^^^^^^^^^^^^^^^^^^
  File "/Users/blueberry/Library/CloudStorage/OneDrive-UniversitätZürichUZH/Studium/FS25/SoComp/SC_RP/rp_implementation/SoComp-FS25/myenv/lib/python3.13/site-packages/pandas/core/frame.py", line 4102, in __getitem__
    indexer = self.columns.get_loc(key)
  File "/Users/blueberry/Library/CloudStorage/OneDrive-UniversitätZürichUZH/Studium/FS25/SoComp/SC_RP/rp_implementation/SoComp-FS25/myenv/lib/python3.13/site-packages/pandas/core/indexes/base.py", line 3812, in get_loc
    raise KeyError(key) from err
KeyError: 'sentiment_category'
2025-05-13 17:09:08,192 - __main__ - INFO - Loading data files...
2025-05-13 17:09:08,192 - __main__ - INFO - Loading Reddit posts from: data/raw/reddit_posts_20250506_180725.csv
2025-05-13 17:09:08,195 - __main__ - INFO - Loaded 0 Reddit posts
2025-05-13 17:09:08,195 - __main__ - INFO - Loading Reddit comments from: data/raw/reddit_comments_20250506_180008.csv
2025-05-13 17:09:08,196 - __main__ - INFO - Loaded 6 Reddit comments
2025-05-13 17:09:08,196 - __main__ - INFO - Loading Twitter data from: twitter_data/twitter_sentiment_data.csv
2025-05-13 17:09:08,196 - __main__ - ERROR - Error during sentiment analysis: [Errno 2] No such file or directory: 'twitter_data/twitter_sentiment_data.csv'
Traceback (most recent call last):
  File "/Users/blueberry/Library/CloudStorage/OneDrive-UniversitätZürichUZH/Studium/FS25/SoComp/SC_RP/rp_implementation/SoComp-FS25/sentiment_analyzer.py", line 1169, in main
    outputs = analyzer.run_complete_analysis(
        reddit_posts_file=args.reddit_posts,
        reddit_comments_file=args.reddit_comments,
        twitter_file=args.twitter
    )
  File "/Users/blueberry/Library/CloudStorage/OneDrive-UniversitätZürichUZH/Studium/FS25/SoComp/SC_RP/rp_implementation/SoComp-FS25/sentiment_analyzer.py", line 1020, in run_complete_analysis
    data = self.load_data(reddit_posts_file, reddit_comments_file, twitter_file)
  File "/Users/blueberry/Library/CloudStorage/OneDrive-UniversitätZürichUZH/Studium/FS25/SoComp/SC_RP/rp_implementation/SoComp-FS25/sentiment_analyzer.py", line 117, in load_data
    data['twitter'] = pd.read_csv(twitter_file)
                      ~~~~~~~~~~~^^^^^^^^^^^^^^
  File "/Users/blueberry/Library/CloudStorage/OneDrive-UniversitätZürichUZH/Studium/FS25/SoComp/SC_RP/rp_implementation/SoComp-FS25/myenv/lib/python3.13/site-packages/pandas/io/parsers/readers.py", line 1026, in read_csv
    return _read(filepath_or_buffer, kwds)
  File "/Users/blueberry/Library/CloudStorage/OneDrive-UniversitätZürichUZH/Studium/FS25/SoComp/SC_RP/rp_implementation/SoComp-FS25/myenv/lib/python3.13/site-packages/pandas/io/parsers/readers.py", line 620, in _read
    parser = TextFileReader(filepath_or_buffer, **kwds)
  File "/Users/blueberry/Library/CloudStorage/OneDrive-UniversitätZürichUZH/Studium/FS25/SoComp/SC_RP/rp_implementation/SoComp-FS25/myenv/lib/python3.13/site-packages/pandas/io/parsers/readers.py", line 1620, in __init__
    self._engine = self._make_engine(f, self.engine)
                   ~~~~~~~~~~~~~~~~~^^^^^^^^^^^^^^^^
  File "/Users/blueberry/Library/CloudStorage/OneDrive-UniversitätZürichUZH/Studium/FS25/SoComp/SC_RP/rp_implementation/SoComp-FS25/myenv/lib/python3.13/site-packages/pandas/io/parsers/readers.py", line 1880, in _make_engine
    self.handles = get_handle(
                   ~~~~~~~~~~^
        f,
        ^^
    ...<6 lines>...
        storage_options=self.options.get("storage_options", None),
        ^^^^^^^^^^^^^^^^^^^^^^^^^^^^^^^^^^^^^^^^^^^^^^^^^^^^^^^^^^
    )
    ^
  File "/Users/blueberry/Library/CloudStorage/OneDrive-UniversitätZürichUZH/Studium/FS25/SoComp/SC_RP/rp_implementation/SoComp-FS25/myenv/lib/python3.13/site-packages/pandas/io/common.py", line 873, in get_handle
    handle = open(
        handle,
    ...<3 lines>...
        newline="",
    )
FileNotFoundError: [Errno 2] No such file or directory: 'twitter_data/twitter_sentiment_data.csv'
2025-05-13 17:10:45,099 - __main__ - INFO - Loading data files...
2025-05-13 17:10:45,099 - __main__ - INFO - Loading Reddit posts from: data/raw/reddit_posts_20250506_180725.csv
2025-05-13 17:10:45,103 - __main__ - INFO - Loaded 0 Reddit posts
2025-05-13 17:10:45,104 - __main__ - INFO - Loading Reddit comments from: data/raw/reddit_comments_20250506_180008.csv
2025-05-13 17:10:45,105 - __main__ - INFO - Loaded 6 Reddit comments
2025-05-13 17:10:45,105 - __main__ - INFO - Loading Twitter data from: ./rp_implementation/twitter_data/twitter_sentiment_data.csv
2025-05-13 17:10:45,105 - __main__ - ERROR - Error during sentiment analysis: [Errno 2] No such file or directory: './rp_implementation/twitter_data/twitter_sentiment_data.csv'
Traceback (most recent call last):
  File "/Users/blueberry/Library/CloudStorage/OneDrive-UniversitätZürichUZH/Studium/FS25/SoComp/SC_RP/rp_implementation/SoComp-FS25/sentiment_analyzer.py", line 1169, in main
    outputs = analyzer.run_complete_analysis(
        reddit_posts_file=args.reddit_posts,
        reddit_comments_file=args.reddit_comments,
        twitter_file=args.twitter
    )
  File "/Users/blueberry/Library/CloudStorage/OneDrive-UniversitätZürichUZH/Studium/FS25/SoComp/SC_RP/rp_implementation/SoComp-FS25/sentiment_analyzer.py", line 1020, in run_complete_analysis
    data = self.load_data(reddit_posts_file, reddit_comments_file, twitter_file)
  File "/Users/blueberry/Library/CloudStorage/OneDrive-UniversitätZürichUZH/Studium/FS25/SoComp/SC_RP/rp_implementation/SoComp-FS25/sentiment_analyzer.py", line 117, in load_data
    data['twitter'] = pd.read_csv(twitter_file)
                      ~~~~~~~~~~~^^^^^^^^^^^^^^
  File "/Users/blueberry/Library/CloudStorage/OneDrive-UniversitätZürichUZH/Studium/FS25/SoComp/SC_RP/rp_implementation/SoComp-FS25/myenv/lib/python3.13/site-packages/pandas/io/parsers/readers.py", line 1026, in read_csv
    return _read(filepath_or_buffer, kwds)
  File "/Users/blueberry/Library/CloudStorage/OneDrive-UniversitätZürichUZH/Studium/FS25/SoComp/SC_RP/rp_implementation/SoComp-FS25/myenv/lib/python3.13/site-packages/pandas/io/parsers/readers.py", line 620, in _read
    parser = TextFileReader(filepath_or_buffer, **kwds)
  File "/Users/blueberry/Library/CloudStorage/OneDrive-UniversitätZürichUZH/Studium/FS25/SoComp/SC_RP/rp_implementation/SoComp-FS25/myenv/lib/python3.13/site-packages/pandas/io/parsers/readers.py", line 1620, in __init__
    self._engine = self._make_engine(f, self.engine)
                   ~~~~~~~~~~~~~~~~~^^^^^^^^^^^^^^^^
  File "/Users/blueberry/Library/CloudStorage/OneDrive-UniversitätZürichUZH/Studium/FS25/SoComp/SC_RP/rp_implementation/SoComp-FS25/myenv/lib/python3.13/site-packages/pandas/io/parsers/readers.py", line 1880, in _make_engine
    self.handles = get_handle(
                   ~~~~~~~~~~^
        f,
        ^^
    ...<6 lines>...
        storage_options=self.options.get("storage_options", None),
        ^^^^^^^^^^^^^^^^^^^^^^^^^^^^^^^^^^^^^^^^^^^^^^^^^^^^^^^^^^
    )
    ^
  File "/Users/blueberry/Library/CloudStorage/OneDrive-UniversitätZürichUZH/Studium/FS25/SoComp/SC_RP/rp_implementation/SoComp-FS25/myenv/lib/python3.13/site-packages/pandas/io/common.py", line 873, in get_handle
    handle = open(
        handle,
    ...<3 lines>...
        newline="",
    )
FileNotFoundError: [Errno 2] No such file or directory: './rp_implementation/twitter_data/twitter_sentiment_data.csv'
2025-05-13 17:11:02,910 - __main__ - INFO - Loading data files...
2025-05-13 17:11:02,911 - __main__ - INFO - Loading Reddit posts from: data/raw/reddit_posts_20250506_180725.csv
2025-05-13 17:11:02,911 - __main__ - INFO - Loaded 0 Reddit posts
2025-05-13 17:11:02,912 - __main__ - INFO - Loading Reddit comments from: data/raw/reddit_comments_20250506_180008.csv
2025-05-13 17:11:02,912 - __main__ - INFO - Loaded 6 Reddit comments
2025-05-13 17:11:02,912 - __main__ - INFO - Loading Twitter data from: ./twitter_data/twitter_sentiment_data.csv
2025-05-13 17:11:02,912 - __main__ - ERROR - Error during sentiment analysis: [Errno 2] No such file or directory: './twitter_data/twitter_sentiment_data.csv'
Traceback (most recent call last):
  File "/Users/blueberry/Library/CloudStorage/OneDrive-UniversitätZürichUZH/Studium/FS25/SoComp/SC_RP/rp_implementation/SoComp-FS25/sentiment_analyzer.py", line 1169, in main
    outputs = analyzer.run_complete_analysis(
        reddit_posts_file=args.reddit_posts,
        reddit_comments_file=args.reddit_comments,
        twitter_file=args.twitter
    )
  File "/Users/blueberry/Library/CloudStorage/OneDrive-UniversitätZürichUZH/Studium/FS25/SoComp/SC_RP/rp_implementation/SoComp-FS25/sentiment_analyzer.py", line 1020, in run_complete_analysis
    data = self.load_data(reddit_posts_file, reddit_comments_file, twitter_file)
  File "/Users/blueberry/Library/CloudStorage/OneDrive-UniversitätZürichUZH/Studium/FS25/SoComp/SC_RP/rp_implementation/SoComp-FS25/sentiment_analyzer.py", line 117, in load_data
    data['twitter'] = pd.read_csv(twitter_file)
                      ~~~~~~~~~~~^^^^^^^^^^^^^^
  File "/Users/blueberry/Library/CloudStorage/OneDrive-UniversitätZürichUZH/Studium/FS25/SoComp/SC_RP/rp_implementation/SoComp-FS25/myenv/lib/python3.13/site-packages/pandas/io/parsers/readers.py", line 1026, in read_csv
    return _read(filepath_or_buffer, kwds)
  File "/Users/blueberry/Library/CloudStorage/OneDrive-UniversitätZürichUZH/Studium/FS25/SoComp/SC_RP/rp_implementation/SoComp-FS25/myenv/lib/python3.13/site-packages/pandas/io/parsers/readers.py", line 620, in _read
    parser = TextFileReader(filepath_or_buffer, **kwds)
  File "/Users/blueberry/Library/CloudStorage/OneDrive-UniversitätZürichUZH/Studium/FS25/SoComp/SC_RP/rp_implementation/SoComp-FS25/myenv/lib/python3.13/site-packages/pandas/io/parsers/readers.py", line 1620, in __init__
    self._engine = self._make_engine(f, self.engine)
                   ~~~~~~~~~~~~~~~~~^^^^^^^^^^^^^^^^
  File "/Users/blueberry/Library/CloudStorage/OneDrive-UniversitätZürichUZH/Studium/FS25/SoComp/SC_RP/rp_implementation/SoComp-FS25/myenv/lib/python3.13/site-packages/pandas/io/parsers/readers.py", line 1880, in _make_engine
    self.handles = get_handle(
                   ~~~~~~~~~~^
        f,
        ^^
    ...<6 lines>...
        storage_options=self.options.get("storage_options", None),
        ^^^^^^^^^^^^^^^^^^^^^^^^^^^^^^^^^^^^^^^^^^^^^^^^^^^^^^^^^^
    )
    ^
  File "/Users/blueberry/Library/CloudStorage/OneDrive-UniversitätZürichUZH/Studium/FS25/SoComp/SC_RP/rp_implementation/SoComp-FS25/myenv/lib/python3.13/site-packages/pandas/io/common.py", line 873, in get_handle
    handle = open(
        handle,
    ...<3 lines>...
        newline="",
    )
FileNotFoundError: [Errno 2] No such file or directory: './twitter_data/twitter_sentiment_data.csv'
2025-05-13 17:11:20,243 - __main__ - INFO - Loading data files...
2025-05-13 17:11:20,243 - __main__ - INFO - Loading Reddit posts from: data/raw/reddit_posts_20250506_180725.csv
2025-05-13 17:11:20,244 - __main__ - INFO - Loaded 0 Reddit posts
2025-05-13 17:11:20,244 - __main__ - INFO - Loading Reddit comments from: data/raw/reddit_comments_20250506_180008.csv
2025-05-13 17:11:20,245 - __main__ - INFO - Loaded 6 Reddit comments
2025-05-13 17:11:20,245 - __main__ - INFO - Loading Twitter data from: /Users/blueberry/Library/CloudStorage/OneDrive-UniversitätZürichUZH/Studium/FS25/SoComp/SC_RP/rp_implementation/twitter_data/twitter_sentiment_data.csv
2025-05-13 17:11:20,292 - __main__ - INFO - Loaded 43943 Twitter posts
2025-05-13 17:11:20,292 - __main__ - INFO - Analyzing sentiment for reddit_comments...
2025-05-13 17:11:20,292 - __main__ - INFO - Applying sentiment analysis to 6 items...
2025-05-13 17:11:20,324 - __main__ - INFO - Sentiment analysis complete
2025-05-13 17:11:20,324 - __main__ - INFO - Analyzing sentiment for twitter...
2025-05-13 17:11:20,324 - __main__ - INFO - Applying sentiment analysis to 43943 items...
2025-05-13 17:11:23,585 - __main__ - INFO - Sentiment analysis complete
2025-05-13 17:11:23,585 - __main__ - INFO - Computing sentiment statistics...
2025-05-13 17:11:23,586 - __main__ - ERROR - Error during sentiment analysis: 'sentiment_category'
Traceback (most recent call last):
  File "/Users/blueberry/Library/CloudStorage/OneDrive-UniversitätZürichUZH/Studium/FS25/SoComp/SC_RP/rp_implementation/SoComp-FS25/myenv/lib/python3.13/site-packages/pandas/core/indexes/base.py", line 3805, in get_loc
    return self._engine.get_loc(casted_key)
           ~~~~~~~~~~~~~~~~~~~~^^^^^^^^^^^^
  File "index.pyx", line 167, in pandas._libs.index.IndexEngine.get_loc
  File "index.pyx", line 196, in pandas._libs.index.IndexEngine.get_loc
  File "pandas/_libs/hashtable_class_helper.pxi", line 7081, in pandas._libs.hashtable.PyObjectHashTable.get_item
  File "pandas/_libs/hashtable_class_helper.pxi", line 7089, in pandas._libs.hashtable.PyObjectHashTable.get_item
KeyError: 'sentiment_category'

The above exception was the direct cause of the following exception:

Traceback (most recent call last):
  File "/Users/blueberry/Library/CloudStorage/OneDrive-UniversitätZürichUZH/Studium/FS25/SoComp/SC_RP/rp_implementation/SoComp-FS25/sentiment_analyzer.py", line 1169, in main
    outputs = analyzer.run_complete_analysis(
        reddit_posts_file=args.reddit_posts,
        reddit_comments_file=args.reddit_comments,
        twitter_file=args.twitter
    )
  File "/Users/blueberry/Library/CloudStorage/OneDrive-UniversitätZürichUZH/Studium/FS25/SoComp/SC_RP/rp_implementation/SoComp-FS25/sentiment_analyzer.py", line 1044, in run_complete_analysis
    sentiment_stats = self.compute_sentiment_stats(analyzed_data)
  File "/Users/blueberry/Library/CloudStorage/OneDrive-UniversitätZürichUZH/Studium/FS25/SoComp/SC_RP/rp_implementation/SoComp-FS25/sentiment_analyzer.py", line 250, in compute_sentiment_stats
    sentiment_counts = df['sentiment_category'].value_counts(normalize=True).to_dict()
                       ~~^^^^^^^^^^^^^^^^^^^^^^
  File "/Users/blueberry/Library/CloudStorage/OneDrive-UniversitätZürichUZH/Studium/FS25/SoComp/SC_RP/rp_implementation/SoComp-FS25/myenv/lib/python3.13/site-packages/pandas/core/frame.py", line 4102, in __getitem__
    indexer = self.columns.get_loc(key)
  File "/Users/blueberry/Library/CloudStorage/OneDrive-UniversitätZürichUZH/Studium/FS25/SoComp/SC_RP/rp_implementation/SoComp-FS25/myenv/lib/python3.13/site-packages/pandas/core/indexes/base.py", line 3812, in get_loc
    raise KeyError(key) from err
KeyError: 'sentiment_category'
2025-05-13 17:14:00,341 - __main__ - INFO - Loading data files...
2025-05-13 17:14:00,341 - __main__ - INFO - Loading Reddit posts from: data/raw/reddit_posts_20250506_180725.csv
2025-05-13 17:14:00,342 - __main__ - INFO - Loaded 0 Reddit posts
2025-05-13 17:14:00,342 - __main__ - INFO - Loading Reddit comments from: data/raw/reddit_comments_20250506_180008.csv
2025-05-13 17:14:00,343 - __main__ - INFO - Loaded 6 Reddit comments
2025-05-13 17:14:00,343 - __main__ - INFO - Loading Twitter data from: /Users/blueberry/Library/CloudStorage/OneDrive-UniversitätZürichUZH/Studium/FS25/SoComp/SC_RP/rp_implementation/twitter_data/twitter_sentiment_data.csv
2025-05-13 17:14:00,390 - __main__ - INFO - Loaded 43943 Twitter posts
2025-05-13 17:14:00,391 - __main__ - INFO - Analyzing sentiment for reddit_comments...
2025-05-13 17:14:00,391 - __main__ - INFO - Applying sentiment analysis to 6 items...
2025-05-13 17:14:00,410 - __main__ - INFO - Sentiment analysis complete
2025-05-13 17:14:00,410 - __main__ - INFO - Analyzing sentiment for twitter...
2025-05-13 17:14:00,410 - __main__ - INFO - Applying sentiment analysis to 43943 items...
2025-05-13 17:14:03,672 - __main__ - INFO - Sentiment analysis complete
2025-05-13 17:14:03,672 - __main__ - INFO - Computing sentiment statistics...
2025-05-13 17:14:03,672 - __main__ - ERROR - Error during sentiment analysis: 'sentiment_category'
Traceback (most recent call last):
  File "/Users/blueberry/Library/CloudStorage/OneDrive-UniversitätZürichUZH/Studium/FS25/SoComp/SC_RP/rp_implementation/SoComp-FS25/myenv/lib/python3.13/site-packages/pandas/core/indexes/base.py", line 3805, in get_loc
    return self._engine.get_loc(casted_key)
           ~~~~~~~~~~~~~~~~~~~~^^^^^^^^^^^^
  File "index.pyx", line 167, in pandas._libs.index.IndexEngine.get_loc
  File "index.pyx", line 196, in pandas._libs.index.IndexEngine.get_loc
  File "pandas/_libs/hashtable_class_helper.pxi", line 7081, in pandas._libs.hashtable.PyObjectHashTable.get_item
  File "pandas/_libs/hashtable_class_helper.pxi", line 7089, in pandas._libs.hashtable.PyObjectHashTable.get_item
KeyError: 'sentiment_category'

The above exception was the direct cause of the following exception:

Traceback (most recent call last):
  File "/Users/blueberry/Library/CloudStorage/OneDrive-UniversitätZürichUZH/Studium/FS25/SoComp/SC_RP/rp_implementation/SoComp-FS25/sentiment_analyzer.py", line 1169, in main
    outputs = analyzer.run_complete_analysis(
        reddit_posts_file=args.reddit_posts,
        reddit_comments_file=args.reddit_comments,
        twitter_file=args.twitter
    )
  File "/Users/blueberry/Library/CloudStorage/OneDrive-UniversitätZürichUZH/Studium/FS25/SoComp/SC_RP/rp_implementation/SoComp-FS25/sentiment_analyzer.py", line 1044, in run_complete_analysis
    sentiment_stats = self.compute_sentiment_stats(analyzed_data)
  File "/Users/blueberry/Library/CloudStorage/OneDrive-UniversitätZürichUZH/Studium/FS25/SoComp/SC_RP/rp_implementation/SoComp-FS25/sentiment_analyzer.py", line 250, in compute_sentiment_stats
    sentiment_counts = df['sentiment_category'].value_counts(normalize=True).to_dict()
                       ~~^^^^^^^^^^^^^^^^^^^^^^
  File "/Users/blueberry/Library/CloudStorage/OneDrive-UniversitätZürichUZH/Studium/FS25/SoComp/SC_RP/rp_implementation/SoComp-FS25/myenv/lib/python3.13/site-packages/pandas/core/frame.py", line 4102, in __getitem__
    indexer = self.columns.get_loc(key)
  File "/Users/blueberry/Library/CloudStorage/OneDrive-UniversitätZürichUZH/Studium/FS25/SoComp/SC_RP/rp_implementation/SoComp-FS25/myenv/lib/python3.13/site-packages/pandas/core/indexes/base.py", line 3812, in get_loc
    raise KeyError(key) from err
KeyError: 'sentiment_category'
2025-05-13 17:18:43,620 - __main__ - INFO - Loading data files...
2025-05-13 17:18:43,621 - __main__ - INFO - Loading Reddit posts from: data/raw/reddit_posts_20250506_180725.csv
2025-05-13 17:18:43,622 - __main__ - INFO - Loaded 0 Reddit posts
2025-05-13 17:18:43,622 - __main__ - INFO - Loading Reddit comments from: data/raw/reddit_comments_20250506_180008.csv
2025-05-13 17:18:43,623 - __main__ - INFO - Loaded 6 Reddit comments
2025-05-13 17:18:43,623 - __main__ - INFO - Loading Twitter data from: /Users/blueberry/Library/CloudStorage/OneDrive-UniversitätZürichUZH/Studium/FS25/SoComp/SC_RP/rp_implementation/twitter_data/twitter_sentiment_data.csv
2025-05-13 17:18:43,672 - __main__ - INFO - Loaded 43943 Twitter posts
2025-05-13 17:18:43,673 - __main__ - INFO - Analyzing sentiment for reddit_comments...
2025-05-13 17:18:43,673 - __main__ - INFO - Applying sentiment analysis to 6 items...
2025-05-13 17:18:43,685 - __main__ - ERROR - Error during sentiment analysis: ('sentiment_category', None)
Traceback (most recent call last):
  File "/Users/blueberry/Library/CloudStorage/OneDrive-UniversitätZürichUZH/Studium/FS25/SoComp/SC_RP/rp_implementation/SoComp-FS25/sentiment_analyzer.py", line 1169, in main
    outputs = analyzer.run_complete_analysis(
        reddit_posts_file=args.reddit_posts,
        reddit_comments_file=args.reddit_comments,
        twitter_file=args.twitter
    )
  File "/Users/blueberry/Library/CloudStorage/OneDrive-UniversitätZürichUZH/Studium/FS25/SoComp/SC_RP/rp_implementation/SoComp-FS25/sentiment_analyzer.py", line 1032, in run_complete_analysis
    analyzed_data[key] = self.apply_sentiment_analysis(df, text_column)
                         ~~~~~~~~~~~~~~~~~~~~~~~~~~~~~^^^^^^^^^^^^^^^^^
  File "/Users/blueberry/Library/CloudStorage/OneDrive-UniversitätZürichUZH/Studium/FS25/SoComp/SC_RP/rp_implementation/SoComp-FS25/sentiment_analyzer.py", line 194, in apply_sentiment_analysis
    batch['sentiment_category'] = sentiments.apply(lambda x: x['sentiment_category', None])
                                  ~~~~~~~~~~~~~~~~^^^^^^^^^^^^^^^^^^^^^^^^^^^^^^^^^^^^^^^^^
  File "/Users/blueberry/Library/CloudStorage/OneDrive-UniversitätZürichUZH/Studium/FS25/SoComp/SC_RP/rp_implementation/SoComp-FS25/myenv/lib/python3.13/site-packages/pandas/core/series.py", line 4924, in apply
    ).apply()
      ~~~~~^^
  File "/Users/blueberry/Library/CloudStorage/OneDrive-UniversitätZürichUZH/Studium/FS25/SoComp/SC_RP/rp_implementation/SoComp-FS25/myenv/lib/python3.13/site-packages/pandas/core/apply.py", line 1427, in apply
    return self.apply_standard()
           ~~~~~~~~~~~~~~~~~~~^^
  File "/Users/blueberry/Library/CloudStorage/OneDrive-UniversitätZürichUZH/Studium/FS25/SoComp/SC_RP/rp_implementation/SoComp-FS25/myenv/lib/python3.13/site-packages/pandas/core/apply.py", line 1507, in apply_standard
    mapped = obj._map_values(
        mapper=curried, na_action=action, convert=self.convert_dtype
    )
  File "/Users/blueberry/Library/CloudStorage/OneDrive-UniversitätZürichUZH/Studium/FS25/SoComp/SC_RP/rp_implementation/SoComp-FS25/myenv/lib/python3.13/site-packages/pandas/core/base.py", line 921, in _map_values
    return algorithms.map_array(arr, mapper, na_action=na_action, convert=convert)
           ~~~~~~~~~~~~~~~~~~~~^^^^^^^^^^^^^^^^^^^^^^^^^^^^^^^^^^^^^^^^^^^^^^^^^^^
  File "/Users/blueberry/Library/CloudStorage/OneDrive-UniversitätZürichUZH/Studium/FS25/SoComp/SC_RP/rp_implementation/SoComp-FS25/myenv/lib/python3.13/site-packages/pandas/core/algorithms.py", line 1743, in map_array
    return lib.map_infer(values, mapper, convert=convert)
           ~~~~~~~~~~~~~^^^^^^^^^^^^^^^^^^^^^^^^^^^^^^^^^
  File "lib.pyx", line 2972, in pandas._libs.lib.map_infer
  File "/Users/blueberry/Library/CloudStorage/OneDrive-UniversitätZürichUZH/Studium/FS25/SoComp/SC_RP/rp_implementation/SoComp-FS25/sentiment_analyzer.py", line 194, in <lambda>
    batch['sentiment_category'] = sentiments.apply(lambda x: x['sentiment_category', None])
                                                             ~^^^^^^^^^^^^^^^^^^^^^^^^^^^^
KeyError: ('sentiment_category', None)
2025-05-13 17:19:57,960 - __main__ - INFO - Loading data files...
2025-05-13 17:19:57,961 - __main__ - INFO - Loading Reddit posts from: data/raw/reddit_posts_20250506_180725.csv
2025-05-13 17:19:57,961 - __main__ - INFO - Loaded 0 Reddit posts
2025-05-13 17:19:57,962 - __main__ - INFO - Loading Reddit comments from: data/raw/reddit_comments_20250506_180008.csv
2025-05-13 17:19:57,962 - __main__ - INFO - Loaded 6 Reddit comments
2025-05-13 17:19:57,962 - __main__ - INFO - Loading Twitter data from: /Users/blueberry/Library/CloudStorage/OneDrive-UniversitätZürichUZH/Studium/FS25/SoComp/SC_RP/rp_implementation/twitter_data/twitter_sentiment_data.csv
2025-05-13 17:19:58,009 - __main__ - INFO - Loaded 43943 Twitter posts
2025-05-13 17:19:58,009 - __main__ - INFO - Analyzing sentiment for reddit_comments...
2025-05-13 17:19:58,009 - __main__ - INFO - Applying sentiment analysis to 6 items...
2025-05-13 17:19:58,028 - __main__ - INFO - Sentiment analysis complete
2025-05-13 17:19:58,028 - __main__ - INFO - Analyzing sentiment for twitter...
2025-05-13 17:19:58,028 - __main__ - INFO - Applying sentiment analysis to 43943 items...
2025-05-13 17:20:01,276 - __main__ - INFO - Sentiment analysis complete
2025-05-13 17:20:01,277 - __main__ - INFO - Computing sentiment statistics...
2025-05-13 17:20:01,277 - __main__ - ERROR - Error during sentiment analysis: 'sentiment_category'
Traceback (most recent call last):
  File "/Users/blueberry/Library/CloudStorage/OneDrive-UniversitätZürichUZH/Studium/FS25/SoComp/SC_RP/rp_implementation/SoComp-FS25/myenv/lib/python3.13/site-packages/pandas/core/indexes/base.py", line 3805, in get_loc
    return self._engine.get_loc(casted_key)
           ~~~~~~~~~~~~~~~~~~~~^^^^^^^^^^^^
  File "index.pyx", line 167, in pandas._libs.index.IndexEngine.get_loc
  File "index.pyx", line 196, in pandas._libs.index.IndexEngine.get_loc
  File "pandas/_libs/hashtable_class_helper.pxi", line 7081, in pandas._libs.hashtable.PyObjectHashTable.get_item
  File "pandas/_libs/hashtable_class_helper.pxi", line 7089, in pandas._libs.hashtable.PyObjectHashTable.get_item
KeyError: 'sentiment_category'

The above exception was the direct cause of the following exception:

Traceback (most recent call last):
  File "/Users/blueberry/Library/CloudStorage/OneDrive-UniversitätZürichUZH/Studium/FS25/SoComp/SC_RP/rp_implementation/SoComp-FS25/sentiment_analyzer.py", line 1169, in main
    outputs = analyzer.run_complete_analysis(
        reddit_posts_file=args.reddit_posts,
        reddit_comments_file=args.reddit_comments,
        twitter_file=args.twitter
    )
  File "/Users/blueberry/Library/CloudStorage/OneDrive-UniversitätZürichUZH/Studium/FS25/SoComp/SC_RP/rp_implementation/SoComp-FS25/sentiment_analyzer.py", line 1044, in run_complete_analysis
    sentiment_stats = self.compute_sentiment_stats(analyzed_data)
  File "/Users/blueberry/Library/CloudStorage/OneDrive-UniversitätZürichUZH/Studium/FS25/SoComp/SC_RP/rp_implementation/SoComp-FS25/sentiment_analyzer.py", line 250, in compute_sentiment_stats
    sentiment_counts = df['sentiment_category'].value_counts(normalize=True).to_dict()
                       ~~^^^^^^^^^^^^^^^^^^^^^^
  File "/Users/blueberry/Library/CloudStorage/OneDrive-UniversitätZürichUZH/Studium/FS25/SoComp/SC_RP/rp_implementation/SoComp-FS25/myenv/lib/python3.13/site-packages/pandas/core/frame.py", line 4102, in __getitem__
    indexer = self.columns.get_loc(key)
  File "/Users/blueberry/Library/CloudStorage/OneDrive-UniversitätZürichUZH/Studium/FS25/SoComp/SC_RP/rp_implementation/SoComp-FS25/myenv/lib/python3.13/site-packages/pandas/core/indexes/base.py", line 3812, in get_loc
    raise KeyError(key) from err
KeyError: 'sentiment_category'
2025-05-13 17:25:56,129 - __main__ - INFO - Loading data files...
2025-05-13 17:25:56,130 - __main__ - INFO - Loading Reddit posts from: data/raw/reddit_posts_20250506_180725.csv
2025-05-13 17:25:56,131 - __main__ - INFO - Loaded 0 Reddit posts
2025-05-13 17:25:56,131 - __main__ - INFO - Loading Reddit comments from: data/raw/reddit_comments_20250506_180008.csv
2025-05-13 17:25:56,132 - __main__ - INFO - Loaded 6 Reddit comments
2025-05-13 17:25:56,132 - __main__ - INFO - Loading Twitter data from: /Users/blueberry/Library/CloudStorage/OneDrive-UniversitätZürichUZH/Studium/FS25/SoComp/SC_RP/rp_implementation/twitter_data/twitter_sentiment_data.csv
2025-05-13 17:25:56,177 - __main__ - INFO - Loaded 43943 Twitter posts
2025-05-13 17:25:56,177 - __main__ - INFO - Analyzing sentiment for reddit_comments...
2025-05-13 17:25:56,177 - __main__ - INFO - Applying sentiment analysis to 6 items...
2025-05-13 17:25:56,192 - __main__ - ERROR - Column 'sentiment_category' is missing after sentiment analysis.
2025-05-13 17:25:56,193 - __main__ - ERROR - Error during sentiment analysis: Sentiment analysis failed to populate 'sentiment_category'.
Traceback (most recent call last):
  File "/Users/blueberry/Library/CloudStorage/OneDrive-UniversitätZürichUZH/Studium/FS25/SoComp/SC_RP/rp_implementation/SoComp-FS25/sentiment_analyzer.py", line 1173, in main
    outputs = analyzer.run_complete_analysis(
        reddit_posts_file=args.reddit_posts,
        reddit_comments_file=args.reddit_comments,
        twitter_file=args.twitter
    )
  File "/Users/blueberry/Library/CloudStorage/OneDrive-UniversitätZürichUZH/Studium/FS25/SoComp/SC_RP/rp_implementation/SoComp-FS25/sentiment_analyzer.py", line 1036, in run_complete_analysis
    analyzed_data[key] = self.apply_sentiment_analysis(df, text_column)
                         ~~~~~~~~~~~~~~~~~~~~~~~~~~~~~^^^^^^^^^^^^^^^^^
  File "/Users/blueberry/Library/CloudStorage/OneDrive-UniversitätZürichUZH/Studium/FS25/SoComp/SC_RP/rp_implementation/SoComp-FS25/sentiment_analyzer.py", line 201, in apply_sentiment_analysis
    raise ValueError("Sentiment analysis failed to populate 'sentiment_category'.")
ValueError: Sentiment analysis failed to populate 'sentiment_category'.
2025-05-13 17:35:24,993 - __main__ - INFO - Loading data files...
2025-05-13 17:35:24,994 - __main__ - INFO - Loading Reddit posts from: data/raw/reddit_posts_20250506_180725.csv
2025-05-13 17:35:24,997 - __main__ - INFO - Loaded 0 Reddit posts
2025-05-13 17:35:24,998 - __main__ - INFO - Loading Reddit comments from: data/raw/reddit_comments_20250506_180008.csv
2025-05-13 17:35:24,998 - __main__ - INFO - Loaded 6 Reddit comments
2025-05-13 17:35:24,998 - __main__ - INFO - Loading Twitter data from: /Users/blueberry/Library/CloudStorage/OneDrive-UniversitätZürichUZH/Studium/FS25/SoComp/SC_RP/rp_implementation/twitter_data/twitter_sentiment_data.csv
2025-05-13 17:35:25,047 - __main__ - INFO - Loaded 43943 Twitter posts
2025-05-13 17:35:25,047 - __main__ - INFO - Analyzing sentiment for reddit_comments...
2025-05-13 17:35:25,047 - __main__ - INFO - Applying sentiment analysis to 6 items...
2025-05-13 17:35:25,073 - __main__ - INFO - Sentiment analysis complete
2025-05-13 17:35:25,074 - __main__ - INFO - Analyzing sentiment for twitter...
2025-05-13 17:35:25,074 - __main__ - INFO - Applying sentiment analysis to 43943 items...
2025-05-13 17:35:28,343 - __main__ - INFO - Sentiment analysis complete
2025-05-13 17:35:28,343 - __main__ - INFO - Computing sentiment statistics...
2025-05-13 17:35:28,357 - __main__ - INFO - Generating visualizations...
2025-05-13 17:35:29,124 - __main__ - INFO - Saved sentiment distribution plot to: data/sentiment/visualizations/sentiment_distribution.png
2025-05-13 17:35:29,264 - __main__ - INFO - Saved sentiment by content length plot to: data/sentiment/visualizations/sentiment_by_length.png
2025-05-13 17:35:29,284 - __main__ - WARNING - No engagement metrics found for twitter
2025-05-13 17:35:29,424 - __main__ - INFO - Saved sentiment by engagement plot to: data/sentiment/visualizations/sentiment_by_engagement.png
2025-05-13 17:35:29,425 - __main__ - INFO - Generating top words visualizations...
2025-05-13 17:35:29,425 - __main__ - ERROR - Error during sentiment analysis: 'cleaned_text'
Traceback (most recent call last):
  File "/Users/blueberry/Library/CloudStorage/OneDrive-UniversitätZürichUZH/Studium/FS25/SoComp/SC_RP/rp_implementation/SoComp-FS25/myenv/lib/python3.13/site-packages/pandas/core/indexes/base.py", line 3805, in get_loc
    return self._engine.get_loc(casted_key)
           ~~~~~~~~~~~~~~~~~~~~^^^^^^^^^^^^
  File "index.pyx", line 167, in pandas._libs.index.IndexEngine.get_loc
  File "index.pyx", line 196, in pandas._libs.index.IndexEngine.get_loc
  File "pandas/_libs/hashtable_class_helper.pxi", line 7081, in pandas._libs.hashtable.PyObjectHashTable.get_item
  File "pandas/_libs/hashtable_class_helper.pxi", line 7089, in pandas._libs.hashtable.PyObjectHashTable.get_item
KeyError: 'cleaned_text'

The above exception was the direct cause of the following exception:

Traceback (most recent call last):
  File "/Users/blueberry/Library/CloudStorage/OneDrive-UniversitätZürichUZH/Studium/FS25/SoComp/SC_RP/rp_implementation/SoComp-FS25/sentiment_analyzer.py", line 1178, in main
    outputs = analyzer.run_complete_analysis(
        reddit_posts_file=args.reddit_posts,
        reddit_comments_file=args.reddit_comments,
        twitter_file=args.twitter
    )
  File "/Users/blueberry/Library/CloudStorage/OneDrive-UniversitätZürichUZH/Studium/FS25/SoComp/SC_RP/rp_implementation/SoComp-FS25/sentiment_analyzer.py", line 1079, in run_complete_analysis
    top_words_visualizations = self.plot_top_words_by_sentiment(analyzed_data, viz_dir)
  File "/Users/blueberry/Library/CloudStorage/OneDrive-UniversitätZürichUZH/Studium/FS25/SoComp/SC_RP/rp_implementation/SoComp-FS25/sentiment_analyzer.py", line 478, in plot_top_words_by_sentiment
    top_words = self.generate_top_words_by_sentiment(df)
  File "/Users/blueberry/Library/CloudStorage/OneDrive-UniversitätZürichUZH/Studium/FS25/SoComp/SC_RP/rp_implementation/SoComp-FS25/sentiment_analyzer.py", line 449, in generate_top_words_by_sentiment
    all_text = ' '.join(category_df[text_column].fillna(''))
                        ~~~~~~~~~~~^^^^^^^^^^^^^
  File "/Users/blueberry/Library/CloudStorage/OneDrive-UniversitätZürichUZH/Studium/FS25/SoComp/SC_RP/rp_implementation/SoComp-FS25/myenv/lib/python3.13/site-packages/pandas/core/frame.py", line 4102, in __getitem__
    indexer = self.columns.get_loc(key)
  File "/Users/blueberry/Library/CloudStorage/OneDrive-UniversitätZürichUZH/Studium/FS25/SoComp/SC_RP/rp_implementation/SoComp-FS25/myenv/lib/python3.13/site-packages/pandas/core/indexes/base.py", line 3812, in get_loc
    raise KeyError(key) from err
KeyError: 'cleaned_text'
2025-05-13 17:44:15,038 - __main__ - INFO - Loading data files...
2025-05-13 17:44:15,039 - __main__ - INFO - Loading Twitter data from: /Users/blueberry/Library/CloudStorage/OneDrive-UniversitätZürichUZH/Studium/FS25/SoComp/SC_RP/rp_implementation/twitter_data/twitter_sentiment_data.csv
2025-05-13 17:44:15,091 - __main__ - INFO - Loaded 43943 Twitter posts
2025-05-13 17:44:15,092 - __main__ - INFO - Analyzing sentiment for twitter...
2025-05-13 17:44:15,092 - __main__ - INFO - Applying sentiment analysis to 43943 items...
2025-05-13 17:44:18,335 - __main__ - INFO - Sentiment analysis complete
2025-05-13 17:44:18,335 - __main__ - INFO - Computing sentiment statistics...
2025-05-13 17:44:18,348 - __main__ - INFO - Generating visualizations...
2025-05-13 17:44:18,604 - __main__ - INFO - Saved sentiment distribution plot to: data/sentiment/visualizations/sentiment_distribution.png
2025-05-13 17:44:18,746 - __main__ - INFO - Saved sentiment by content length plot to: data/sentiment/visualizations/sentiment_by_length.png
2025-05-13 17:44:18,754 - __main__ - WARNING - No engagement metrics found for twitter
2025-05-13 17:44:18,885 - __main__ - INFO - Saved sentiment by engagement plot to: data/sentiment/visualizations/sentiment_by_engagement.png
2025-05-13 17:44:18,885 - __main__ - INFO - Generating top words visualizations...
2025-05-13 17:44:18,887 - __main__ - ERROR - Error during sentiment analysis: 'cleaned_text'
Traceback (most recent call last):
  File "/Users/blueberry/Library/CloudStorage/OneDrive-UniversitätZürichUZH/Studium/FS25/SoComp/SC_RP/rp_implementation/SoComp-FS25/myenv/lib/python3.13/site-packages/pandas/core/indexes/base.py", line 3805, in get_loc
    return self._engine.get_loc(casted_key)
           ~~~~~~~~~~~~~~~~~~~~^^^^^^^^^^^^
  File "index.pyx", line 167, in pandas._libs.index.IndexEngine.get_loc
  File "index.pyx", line 196, in pandas._libs.index.IndexEngine.get_loc
  File "pandas/_libs/hashtable_class_helper.pxi", line 7081, in pandas._libs.hashtable.PyObjectHashTable.get_item
  File "pandas/_libs/hashtable_class_helper.pxi", line 7089, in pandas._libs.hashtable.PyObjectHashTable.get_item
KeyError: 'cleaned_text'

The above exception was the direct cause of the following exception:

Traceback (most recent call last):
  File "/Users/blueberry/Library/CloudStorage/OneDrive-UniversitätZürichUZH/Studium/FS25/SoComp/SC_RP/rp_implementation/SoComp-FS25/sentiment_analyzer.py", line 1178, in main
    outputs = analyzer.run_complete_analysis(
        reddit_posts_file=args.reddit_posts,
        reddit_comments_file=args.reddit_comments,
        twitter_file=args.twitter
    )
  File "/Users/blueberry/Library/CloudStorage/OneDrive-UniversitätZürichUZH/Studium/FS25/SoComp/SC_RP/rp_implementation/SoComp-FS25/sentiment_analyzer.py", line 1079, in run_complete_analysis
    top_words_visualizations = self.plot_top_words_by_sentiment(analyzed_data, viz_dir)
  File "/Users/blueberry/Library/CloudStorage/OneDrive-UniversitätZürichUZH/Studium/FS25/SoComp/SC_RP/rp_implementation/SoComp-FS25/sentiment_analyzer.py", line 478, in plot_top_words_by_sentiment
    top_words = self.generate_top_words_by_sentiment(df)
  File "/Users/blueberry/Library/CloudStorage/OneDrive-UniversitätZürichUZH/Studium/FS25/SoComp/SC_RP/rp_implementation/SoComp-FS25/sentiment_analyzer.py", line 449, in generate_top_words_by_sentiment
    all_text = ' '.join(category_df[text_column].fillna(''))
                        ~~~~~~~~~~~^^^^^^^^^^^^^
  File "/Users/blueberry/Library/CloudStorage/OneDrive-UniversitätZürichUZH/Studium/FS25/SoComp/SC_RP/rp_implementation/SoComp-FS25/myenv/lib/python3.13/site-packages/pandas/core/frame.py", line 4102, in __getitem__
    indexer = self.columns.get_loc(key)
  File "/Users/blueberry/Library/CloudStorage/OneDrive-UniversitätZürichUZH/Studium/FS25/SoComp/SC_RP/rp_implementation/SoComp-FS25/myenv/lib/python3.13/site-packages/pandas/core/indexes/base.py", line 3812, in get_loc
    raise KeyError(key) from err
KeyError: 'cleaned_text'
2025-05-13 17:46:24,627 - __main__ - INFO - Loading data files...
2025-05-13 17:46:24,627 - __main__ - INFO - Loading Twitter data from: /Users/blueberry/Library/CloudStorage/OneDrive-UniversitätZürichUZH/Studium/FS25/SoComp/SC_RP/rp_implementation/twitter_data/twitter_sentiment_data.csv
2025-05-13 17:46:24,675 - __main__ - INFO - Loaded 43943 Twitter posts
2025-05-13 17:46:24,675 - __main__ - INFO - Analyzing sentiment for twitter...
2025-05-13 17:46:24,675 - __main__ - INFO - Applying sentiment analysis to 43943 items...
2025-05-13 17:46:27,993 - __main__ - INFO - Sentiment analysis complete
2025-05-13 17:46:27,993 - __main__ - INFO - Computing sentiment statistics...
2025-05-13 17:46:28,006 - __main__ - INFO - Generating visualizations...
2025-05-13 17:46:28,251 - __main__ - INFO - Saved sentiment distribution plot to: data/sentiment/visualizations/sentiment_distribution.png
2025-05-13 17:46:28,396 - __main__ - INFO - Saved sentiment by content length plot to: data/sentiment/visualizations/sentiment_by_length.png
2025-05-13 17:46:28,404 - __main__ - WARNING - No engagement metrics found for twitter
2025-05-13 17:46:28,533 - __main__ - INFO - Saved sentiment by engagement plot to: data/sentiment/visualizations/sentiment_by_engagement.png
2025-05-13 17:46:28,533 - __main__ - INFO - Generating top words visualizations...
2025-05-13 17:46:28,535 - __main__ - ERROR - Error during sentiment analysis: 'cleaned_text'
Traceback (most recent call last):
  File "/Users/blueberry/Library/CloudStorage/OneDrive-UniversitätZürichUZH/Studium/FS25/SoComp/SC_RP/rp_implementation/SoComp-FS25/myenv/lib/python3.13/site-packages/pandas/core/indexes/base.py", line 3805, in get_loc
    return self._engine.get_loc(casted_key)
           ~~~~~~~~~~~~~~~~~~~~^^^^^^^^^^^^
  File "index.pyx", line 167, in pandas._libs.index.IndexEngine.get_loc
  File "index.pyx", line 196, in pandas._libs.index.IndexEngine.get_loc
  File "pandas/_libs/hashtable_class_helper.pxi", line 7081, in pandas._libs.hashtable.PyObjectHashTable.get_item
  File "pandas/_libs/hashtable_class_helper.pxi", line 7089, in pandas._libs.hashtable.PyObjectHashTable.get_item
KeyError: 'cleaned_text'

The above exception was the direct cause of the following exception:

Traceback (most recent call last):
  File "/Users/blueberry/Library/CloudStorage/OneDrive-UniversitätZürichUZH/Studium/FS25/SoComp/SC_RP/rp_implementation/SoComp-FS25/sentiment_analyzer.py", line 1179, in main
    outputs = analyzer.run_complete_analysis(
        reddit_posts_file=args.reddit_posts,
        reddit_comments_file=args.reddit_comments,
        twitter_file=args.twitter
    )
  File "/Users/blueberry/Library/CloudStorage/OneDrive-UniversitätZürichUZH/Studium/FS25/SoComp/SC_RP/rp_implementation/SoComp-FS25/sentiment_analyzer.py", line 1080, in run_complete_analysis
    top_words_visualizations = self.plot_top_words_by_sentiment(analyzed_data, viz_dir)
  File "/Users/blueberry/Library/CloudStorage/OneDrive-UniversitätZürichUZH/Studium/FS25/SoComp/SC_RP/rp_implementation/SoComp-FS25/sentiment_analyzer.py", line 479, in plot_top_words_by_sentiment
    top_words = self.generate_top_words_by_sentiment(df)
  File "/Users/blueberry/Library/CloudStorage/OneDrive-UniversitätZürichUZH/Studium/FS25/SoComp/SC_RP/rp_implementation/SoComp-FS25/sentiment_analyzer.py", line 450, in generate_top_words_by_sentiment
    all_text = ' '.join(category_df[text_column].fillna(''))
                        ~~~~~~~~~~~^^^^^^^^^^^^^
  File "/Users/blueberry/Library/CloudStorage/OneDrive-UniversitätZürichUZH/Studium/FS25/SoComp/SC_RP/rp_implementation/SoComp-FS25/myenv/lib/python3.13/site-packages/pandas/core/frame.py", line 4102, in __getitem__
    indexer = self.columns.get_loc(key)
  File "/Users/blueberry/Library/CloudStorage/OneDrive-UniversitätZürichUZH/Studium/FS25/SoComp/SC_RP/rp_implementation/SoComp-FS25/myenv/lib/python3.13/site-packages/pandas/core/indexes/base.py", line 3812, in get_loc
    raise KeyError(key) from err
KeyError: 'cleaned_text'
2025-05-13 17:53:07,318 - __main__ - INFO - Loading data files...
2025-05-13 17:53:07,319 - __main__ - INFO - Loading Twitter data from: /Users/blueberry/Library/CloudStorage/OneDrive-UniversitätZürichUZH/Studium/FS25/SoComp/SC_RP/rp_implementation/twitter_data/twitter_sentiment_data.csv
2025-05-13 17:53:07,368 - __main__ - INFO - Loaded 43943 Twitter posts
2025-05-13 17:53:07,369 - __main__ - INFO - Analyzing sentiment for twitter...
2025-05-13 17:53:07,369 - __main__ - INFO - Applying sentiment analysis to 43943 items...
2025-05-13 17:53:10,645 - __main__ - INFO - Sentiment analysis complete
2025-05-13 17:53:10,645 - __main__ - INFO - Computing sentiment statistics...
2025-05-13 17:53:10,659 - __main__ - INFO - Generating visualizations...
2025-05-13 17:53:10,900 - __main__ - INFO - Saved sentiment distribution plot to: data/sentiment/visualizations/sentiment_distribution.png
2025-05-13 17:53:11,041 - __main__ - INFO - Saved sentiment by content length plot to: data/sentiment/visualizations/sentiment_by_length.png
2025-05-13 17:53:11,049 - __main__ - WARNING - No engagement metrics found for twitter
2025-05-13 17:53:11,178 - __main__ - INFO - Saved sentiment by engagement plot to: data/sentiment/visualizations/sentiment_by_engagement.png
2025-05-13 17:53:11,178 - __main__ - INFO - Generating top words visualizations...
2025-05-13 17:53:11,180 - __main__ - ERROR - Error during sentiment analysis: 'cleaned_text'
Traceback (most recent call last):
  File "/Users/blueberry/Library/CloudStorage/OneDrive-UniversitätZürichUZH/Studium/FS25/SoComp/SC_RP/rp_implementation/SoComp-FS25/myenv/lib/python3.13/site-packages/pandas/core/indexes/base.py", line 3805, in get_loc
    return self._engine.get_loc(casted_key)
           ~~~~~~~~~~~~~~~~~~~~^^^^^^^^^^^^
  File "index.pyx", line 167, in pandas._libs.index.IndexEngine.get_loc
  File "index.pyx", line 196, in pandas._libs.index.IndexEngine.get_loc
  File "pandas/_libs/hashtable_class_helper.pxi", line 7081, in pandas._libs.hashtable.PyObjectHashTable.get_item
  File "pandas/_libs/hashtable_class_helper.pxi", line 7089, in pandas._libs.hashtable.PyObjectHashTable.get_item
KeyError: 'cleaned_text'

The above exception was the direct cause of the following exception:

Traceback (most recent call last):
  File "/Users/blueberry/Library/CloudStorage/OneDrive-UniversitätZürichUZH/Studium/FS25/SoComp/SC_RP/rp_implementation/SoComp-FS25/sentiment_analyzer.py", line 1185, in main
    outputs = analyzer.run_complete_analysis(
        reddit_posts_file=args.reddit_posts,
        reddit_comments_file=args.reddit_comments,
        twitter_file=args.twitter
    )
  File "/Users/blueberry/Library/CloudStorage/OneDrive-UniversitätZürichUZH/Studium/FS25/SoComp/SC_RP/rp_implementation/SoComp-FS25/sentiment_analyzer.py", line 1086, in run_complete_analysis
    top_words_visualizations = self.plot_top_words_by_sentiment(analyzed_data, viz_dir)
  File "/Users/blueberry/Library/CloudStorage/OneDrive-UniversitätZürichUZH/Studium/FS25/SoComp/SC_RP/rp_implementation/SoComp-FS25/sentiment_analyzer.py", line 479, in plot_top_words_by_sentiment
    top_words = self.generate_top_words_by_sentiment(df)
  File "/Users/blueberry/Library/CloudStorage/OneDrive-UniversitätZürichUZH/Studium/FS25/SoComp/SC_RP/rp_implementation/SoComp-FS25/sentiment_analyzer.py", line 450, in generate_top_words_by_sentiment
    all_text = ' '.join(category_df[text_column].fillna(''))
                        ~~~~~~~~~~~^^^^^^^^^^^^^
  File "/Users/blueberry/Library/CloudStorage/OneDrive-UniversitätZürichUZH/Studium/FS25/SoComp/SC_RP/rp_implementation/SoComp-FS25/myenv/lib/python3.13/site-packages/pandas/core/frame.py", line 4102, in __getitem__
    indexer = self.columns.get_loc(key)
  File "/Users/blueberry/Library/CloudStorage/OneDrive-UniversitätZürichUZH/Studium/FS25/SoComp/SC_RP/rp_implementation/SoComp-FS25/myenv/lib/python3.13/site-packages/pandas/core/indexes/base.py", line 3812, in get_loc
    raise KeyError(key) from err
KeyError: 'cleaned_text'
2025-05-13 17:55:25,459 - __main__ - INFO - Loading data files...
2025-05-13 17:55:25,459 - __main__ - INFO - Loading Twitter data from: /Users/blueberry/Library/CloudStorage/OneDrive-UniversitätZürichUZH/Studium/FS25/SoComp/SC_RP/rp_implementation/twitter_data/twitter_sentiment_data.csv
2025-05-13 17:55:25,505 - __main__ - INFO - Loaded 43943 Twitter posts
2025-05-13 17:55:25,506 - __main__ - INFO - Analyzing sentiment for twitter...
2025-05-13 17:55:25,506 - __main__ - INFO - Applying sentiment analysis to 43943 items...
2025-05-13 17:55:28,798 - __main__ - INFO - Sentiment analysis complete
2025-05-13 17:55:28,799 - __main__ - INFO - Computing sentiment statistics...
2025-05-13 17:55:28,811 - __main__ - INFO - Generating visualizations...
2025-05-13 17:55:29,058 - __main__ - INFO - Saved sentiment distribution plot to: data/sentiment/visualizations/sentiment_distribution.png
2025-05-13 17:55:29,197 - __main__ - INFO - Saved sentiment by content length plot to: data/sentiment/visualizations/sentiment_by_length.png
2025-05-13 17:55:29,205 - __main__ - WARNING - No engagement metrics found for twitter
2025-05-13 17:55:29,332 - __main__ - INFO - Saved sentiment by engagement plot to: data/sentiment/visualizations/sentiment_by_engagement.png
2025-05-13 17:55:29,332 - __main__ - INFO - Generating top words visualizations...
2025-05-13 17:55:29,334 - __main__ - ERROR - Error during sentiment analysis: 'cleaned_text'
Traceback (most recent call last):
  File "/Users/blueberry/Library/CloudStorage/OneDrive-UniversitätZürichUZH/Studium/FS25/SoComp/SC_RP/rp_implementation/SoComp-FS25/myenv/lib/python3.13/site-packages/pandas/core/indexes/base.py", line 3805, in get_loc
    return self._engine.get_loc(casted_key)
           ~~~~~~~~~~~~~~~~~~~~^^^^^^^^^^^^
  File "index.pyx", line 167, in pandas._libs.index.IndexEngine.get_loc
  File "index.pyx", line 196, in pandas._libs.index.IndexEngine.get_loc
  File "pandas/_libs/hashtable_class_helper.pxi", line 7081, in pandas._libs.hashtable.PyObjectHashTable.get_item
  File "pandas/_libs/hashtable_class_helper.pxi", line 7089, in pandas._libs.hashtable.PyObjectHashTable.get_item
KeyError: 'cleaned_text'

The above exception was the direct cause of the following exception:

Traceback (most recent call last):
  File "/Users/blueberry/Library/CloudStorage/OneDrive-UniversitätZürichUZH/Studium/FS25/SoComp/SC_RP/rp_implementation/SoComp-FS25/sentiment_analyzer.py", line 1183, in main
    outputs = analyzer.run_complete_analysis(
        reddit_posts_file=args.reddit_posts,
        reddit_comments_file=args.reddit_comments,
        twitter_file=args.twitter
    )
  File "/Users/blueberry/Library/CloudStorage/OneDrive-UniversitätZürichUZH/Studium/FS25/SoComp/SC_RP/rp_implementation/SoComp-FS25/sentiment_analyzer.py", line 1084, in run_complete_analysis
    top_words_visualizations = self.plot_top_words_by_sentiment(analyzed_data, viz_dir)
  File "/Users/blueberry/Library/CloudStorage/OneDrive-UniversitätZürichUZH/Studium/FS25/SoComp/SC_RP/rp_implementation/SoComp-FS25/sentiment_analyzer.py", line 477, in plot_top_words_by_sentiment
    top_words = self.generate_top_words_by_sentiment(df)
  File "/Users/blueberry/Library/CloudStorage/OneDrive-UniversitätZürichUZH/Studium/FS25/SoComp/SC_RP/rp_implementation/SoComp-FS25/sentiment_analyzer.py", line 448, in generate_top_words_by_sentiment
    all_text = ' '.join(category_df[text_column].fillna(''))
                        ~~~~~~~~~~~^^^^^^^^^^^^^
  File "/Users/blueberry/Library/CloudStorage/OneDrive-UniversitätZürichUZH/Studium/FS25/SoComp/SC_RP/rp_implementation/SoComp-FS25/myenv/lib/python3.13/site-packages/pandas/core/frame.py", line 4102, in __getitem__
    indexer = self.columns.get_loc(key)
  File "/Users/blueberry/Library/CloudStorage/OneDrive-UniversitätZürichUZH/Studium/FS25/SoComp/SC_RP/rp_implementation/SoComp-FS25/myenv/lib/python3.13/site-packages/pandas/core/indexes/base.py", line 3812, in get_loc
    raise KeyError(key) from err
KeyError: 'cleaned_text'
2025-05-13 17:57:56,790 - __main__ - INFO - Loading data files...
2025-05-13 17:57:56,791 - __main__ - INFO - Loading Twitter data from: /Users/blueberry/Library/CloudStorage/OneDrive-UniversitätZürichUZH/Studium/FS25/SoComp/SC_RP/rp_implementation/twitter_data/twitter_sentiment_data.csv
2025-05-13 17:57:56,843 - __main__ - INFO - Loaded 43943 Twitter posts
2025-05-13 17:57:56,843 - __main__ - INFO - Analyzing sentiment for twitter...
2025-05-13 17:57:56,843 - __main__ - INFO - Applying sentiment analysis to 43943 items...
2025-05-13 17:58:00,142 - __main__ - INFO - Sentiment analysis complete
2025-05-13 17:58:00,143 - __main__ - INFO - Computing sentiment statistics...
2025-05-13 17:58:00,155 - __main__ - INFO - Generating visualizations...
2025-05-13 17:58:00,394 - __main__ - INFO - Saved sentiment distribution plot to: data/sentiment/visualizations/sentiment_distribution.png
2025-05-13 17:58:00,532 - __main__ - INFO - Saved sentiment by content length plot to: data/sentiment/visualizations/sentiment_by_length.png
2025-05-13 17:58:00,540 - __main__ - WARNING - No engagement metrics found for twitter
2025-05-13 17:58:00,670 - __main__ - INFO - Saved sentiment by engagement plot to: data/sentiment/visualizations/sentiment_by_engagement.png
2025-05-13 17:58:00,670 - __main__ - INFO - Generating top words visualizations...
2025-05-13 17:58:00,672 - __main__ - ERROR - Error during sentiment analysis: 'cleaned_text'
Traceback (most recent call last):
  File "/Users/blueberry/Library/CloudStorage/OneDrive-UniversitätZürichUZH/Studium/FS25/SoComp/SC_RP/rp_implementation/SoComp-FS25/myenv/lib/python3.13/site-packages/pandas/core/indexes/base.py", line 3805, in get_loc
    return self._engine.get_loc(casted_key)
           ~~~~~~~~~~~~~~~~~~~~^^^^^^^^^^^^
  File "index.pyx", line 167, in pandas._libs.index.IndexEngine.get_loc
  File "index.pyx", line 196, in pandas._libs.index.IndexEngine.get_loc
  File "pandas/_libs/hashtable_class_helper.pxi", line 7081, in pandas._libs.hashtable.PyObjectHashTable.get_item
  File "pandas/_libs/hashtable_class_helper.pxi", line 7089, in pandas._libs.hashtable.PyObjectHashTable.get_item
KeyError: 'cleaned_text'

The above exception was the direct cause of the following exception:

Traceback (most recent call last):
  File "/Users/blueberry/Library/CloudStorage/OneDrive-UniversitätZürichUZH/Studium/FS25/SoComp/SC_RP/rp_implementation/SoComp-FS25/sentiment_analyzer.py", line 1183, in main
    outputs = analyzer.run_complete_analysis(
        reddit_posts_file=args.reddit_posts,
        reddit_comments_file=args.reddit_comments,
        twitter_file=args.twitter
    )
  File "/Users/blueberry/Library/CloudStorage/OneDrive-UniversitätZürichUZH/Studium/FS25/SoComp/SC_RP/rp_implementation/SoComp-FS25/sentiment_analyzer.py", line 1084, in run_complete_analysis
    top_words_visualizations = self.plot_top_words_by_sentiment(analyzed_data, viz_dir)
  File "/Users/blueberry/Library/CloudStorage/OneDrive-UniversitätZürichUZH/Studium/FS25/SoComp/SC_RP/rp_implementation/SoComp-FS25/sentiment_analyzer.py", line 477, in plot_top_words_by_sentiment
    top_words = self.generate_top_words_by_sentiment(df)
  File "/Users/blueberry/Library/CloudStorage/OneDrive-UniversitätZürichUZH/Studium/FS25/SoComp/SC_RP/rp_implementation/SoComp-FS25/sentiment_analyzer.py", line 448, in generate_top_words_by_sentiment
    all_text = ' '.join(category_df[text_column].fillna(''))
                        ~~~~~~~~~~~^^^^^^^^^^^^^
  File "/Users/blueberry/Library/CloudStorage/OneDrive-UniversitätZürichUZH/Studium/FS25/SoComp/SC_RP/rp_implementation/SoComp-FS25/myenv/lib/python3.13/site-packages/pandas/core/frame.py", line 4102, in __getitem__
    indexer = self.columns.get_loc(key)
  File "/Users/blueberry/Library/CloudStorage/OneDrive-UniversitätZürichUZH/Studium/FS25/SoComp/SC_RP/rp_implementation/SoComp-FS25/myenv/lib/python3.13/site-packages/pandas/core/indexes/base.py", line 3812, in get_loc
    raise KeyError(key) from err
KeyError: 'cleaned_text'
2025-05-13 18:05:56,884 - __main__ - INFO - Loading data files...
2025-05-13 18:05:56,885 - __main__ - INFO - Loading Twitter data from: /Users/blueberry/Library/CloudStorage/OneDrive-UniversitätZürichUZH/Studium/FS25/SoComp/SC_RP/rp_implementation/twitter_data/twitter_sentiment_data.csv
2025-05-13 18:05:56,934 - __main__ - INFO - Loaded 43943 Twitter posts
2025-05-13 18:05:56,935 - __main__ - INFO - Analyzing sentiment for twitter...
2025-05-13 18:05:56,935 - __main__ - INFO - Applying sentiment analysis to 43943 items...
2025-05-13 18:06:00,289 - __main__ - INFO - Sentiment analysis complete
2025-05-13 18:06:00,289 - __main__ - INFO - Computing sentiment statistics...
2025-05-13 18:06:00,303 - __main__ - INFO - Generating visualizations...
2025-05-13 18:06:00,551 - __main__ - INFO - Saved sentiment distribution plot to: data/sentiment/visualizations/sentiment_distribution.png
2025-05-13 18:06:00,693 - __main__ - INFO - Saved sentiment by content length plot to: data/sentiment/visualizations/sentiment_by_length.png
2025-05-13 18:06:00,702 - __main__ - WARNING - No engagement metrics found for twitter
2025-05-13 18:06:00,830 - __main__ - INFO - Saved sentiment by engagement plot to: data/sentiment/visualizations/sentiment_by_engagement.png
2025-05-13 18:06:00,830 - __main__ - INFO - Generating top words visualizations...
2025-05-13 18:06:00,832 - __main__ - ERROR - Error during sentiment analysis: 'cleaned_text'
Traceback (most recent call last):
  File "/Users/blueberry/Library/CloudStorage/OneDrive-UniversitätZürichUZH/Studium/FS25/SoComp/SC_RP/rp_implementation/SoComp-FS25/myenv/lib/python3.13/site-packages/pandas/core/indexes/base.py", line 3805, in get_loc
    return self._engine.get_loc(casted_key)
           ~~~~~~~~~~~~~~~~~~~~^^^^^^^^^^^^
  File "index.pyx", line 167, in pandas._libs.index.IndexEngine.get_loc
  File "index.pyx", line 196, in pandas._libs.index.IndexEngine.get_loc
  File "pandas/_libs/hashtable_class_helper.pxi", line 7081, in pandas._libs.hashtable.PyObjectHashTable.get_item
  File "pandas/_libs/hashtable_class_helper.pxi", line 7089, in pandas._libs.hashtable.PyObjectHashTable.get_item
KeyError: 'cleaned_text'

The above exception was the direct cause of the following exception:

Traceback (most recent call last):
  File "/Users/blueberry/Library/CloudStorage/OneDrive-UniversitätZürichUZH/Studium/FS25/SoComp/SC_RP/rp_implementation/SoComp-FS25/sentiment_analyzer.py", line 1183, in main
    outputs = analyzer.run_complete_analysis(
        reddit_posts_file=args.reddit_posts,
        reddit_comments_file=args.reddit_comments,
        twitter_file=args.twitter
    )
  File "/Users/blueberry/Library/CloudStorage/OneDrive-UniversitätZürichUZH/Studium/FS25/SoComp/SC_RP/rp_implementation/SoComp-FS25/sentiment_analyzer.py", line 1084, in run_complete_analysis
    top_words_visualizations = self.plot_top_words_by_sentiment(analyzed_data, viz_dir)
  File "/Users/blueberry/Library/CloudStorage/OneDrive-UniversitätZürichUZH/Studium/FS25/SoComp/SC_RP/rp_implementation/SoComp-FS25/sentiment_analyzer.py", line 477, in plot_top_words_by_sentiment
    top_words = self.generate_top_words_by_sentiment(df)
  File "/Users/blueberry/Library/CloudStorage/OneDrive-UniversitätZürichUZH/Studium/FS25/SoComp/SC_RP/rp_implementation/SoComp-FS25/sentiment_analyzer.py", line 448, in generate_top_words_by_sentiment
    all_text = ' '.join(category_df[text_column].fillna(''))
                        ~~~~~~~~~~~^^^^^^^^^^^^^
  File "/Users/blueberry/Library/CloudStorage/OneDrive-UniversitätZürichUZH/Studium/FS25/SoComp/SC_RP/rp_implementation/SoComp-FS25/myenv/lib/python3.13/site-packages/pandas/core/frame.py", line 4102, in __getitem__
    indexer = self.columns.get_loc(key)
  File "/Users/blueberry/Library/CloudStorage/OneDrive-UniversitätZürichUZH/Studium/FS25/SoComp/SC_RP/rp_implementation/SoComp-FS25/myenv/lib/python3.13/site-packages/pandas/core/indexes/base.py", line 3812, in get_loc
    raise KeyError(key) from err
KeyError: 'cleaned_text'
2025-05-13 18:06:12,076 - __main__ - INFO - Loading data files...
2025-05-13 18:06:12,077 - __main__ - INFO - Loading Reddit posts from: data/raw/reddit_posts_20250506_180725.csv
2025-05-13 18:06:12,079 - __main__ - INFO - Loaded 0 Reddit posts
2025-05-13 18:06:12,079 - __main__ - INFO - Loading Reddit comments from: data/raw/reddit_comments_20250506_180008.csv
2025-05-13 18:06:12,080 - __main__ - INFO - Loaded 6 Reddit comments
2025-05-13 18:06:12,080 - __main__ - INFO - Loading Twitter data from: /Users/blueberry/Library/CloudStorage/OneDrive-UniversitätZürichUZH/Studium/FS25/SoComp/SC_RP/rp_implementation/twitter_data/twitter_sentiment_data.csv
2025-05-13 18:06:12,131 - __main__ - INFO - Loaded 43943 Twitter posts
2025-05-13 18:06:12,131 - __main__ - INFO - Analyzing sentiment for reddit_comments...
2025-05-13 18:06:12,131 - __main__ - INFO - Applying sentiment analysis to 6 items...
2025-05-13 18:06:12,149 - __main__ - INFO - Sentiment analysis complete
2025-05-13 18:06:12,149 - __main__ - INFO - Analyzing sentiment for twitter...
2025-05-13 18:06:12,149 - __main__ - INFO - Applying sentiment analysis to 43943 items...
2025-05-13 18:06:15,380 - __main__ - INFO - Sentiment analysis complete
2025-05-13 18:06:15,380 - __main__ - INFO - Computing sentiment statistics...
2025-05-13 18:06:15,393 - __main__ - INFO - Generating visualizations...
2025-05-13 18:06:15,634 - __main__ - INFO - Saved sentiment distribution plot to: data/sentiment/visualizations/sentiment_distribution.png
2025-05-13 18:06:15,773 - __main__ - INFO - Saved sentiment by content length plot to: data/sentiment/visualizations/sentiment_by_length.png
2025-05-13 18:06:15,793 - __main__ - WARNING - No engagement metrics found for twitter
2025-05-13 18:06:15,931 - __main__ - INFO - Saved sentiment by engagement plot to: data/sentiment/visualizations/sentiment_by_engagement.png
2025-05-13 18:06:15,931 - __main__ - INFO - Generating top words visualizations...
2025-05-13 18:06:15,932 - __main__ - ERROR - Error during sentiment analysis: 'cleaned_text'
Traceback (most recent call last):
  File "/Users/blueberry/Library/CloudStorage/OneDrive-UniversitätZürichUZH/Studium/FS25/SoComp/SC_RP/rp_implementation/SoComp-FS25/myenv/lib/python3.13/site-packages/pandas/core/indexes/base.py", line 3805, in get_loc
    return self._engine.get_loc(casted_key)
           ~~~~~~~~~~~~~~~~~~~~^^^^^^^^^^^^
  File "index.pyx", line 167, in pandas._libs.index.IndexEngine.get_loc
  File "index.pyx", line 196, in pandas._libs.index.IndexEngine.get_loc
  File "pandas/_libs/hashtable_class_helper.pxi", line 7081, in pandas._libs.hashtable.PyObjectHashTable.get_item
  File "pandas/_libs/hashtable_class_helper.pxi", line 7089, in pandas._libs.hashtable.PyObjectHashTable.get_item
KeyError: 'cleaned_text'

The above exception was the direct cause of the following exception:

Traceback (most recent call last):
  File "/Users/blueberry/Library/CloudStorage/OneDrive-UniversitätZürichUZH/Studium/FS25/SoComp/SC_RP/rp_implementation/SoComp-FS25/sentiment_analyzer.py", line 1183, in main
    outputs = analyzer.run_complete_analysis(
        reddit_posts_file=args.reddit_posts,
        reddit_comments_file=args.reddit_comments,
        twitter_file=args.twitter
    )
  File "/Users/blueberry/Library/CloudStorage/OneDrive-UniversitätZürichUZH/Studium/FS25/SoComp/SC_RP/rp_implementation/SoComp-FS25/sentiment_analyzer.py", line 1084, in run_complete_analysis
    top_words_visualizations = self.plot_top_words_by_sentiment(analyzed_data, viz_dir)
  File "/Users/blueberry/Library/CloudStorage/OneDrive-UniversitätZürichUZH/Studium/FS25/SoComp/SC_RP/rp_implementation/SoComp-FS25/sentiment_analyzer.py", line 477, in plot_top_words_by_sentiment
    top_words = self.generate_top_words_by_sentiment(df)
  File "/Users/blueberry/Library/CloudStorage/OneDrive-UniversitätZürichUZH/Studium/FS25/SoComp/SC_RP/rp_implementation/SoComp-FS25/sentiment_analyzer.py", line 448, in generate_top_words_by_sentiment
    all_text = ' '.join(category_df[text_column].fillna(''))
                        ~~~~~~~~~~~^^^^^^^^^^^^^
  File "/Users/blueberry/Library/CloudStorage/OneDrive-UniversitätZürichUZH/Studium/FS25/SoComp/SC_RP/rp_implementation/SoComp-FS25/myenv/lib/python3.13/site-packages/pandas/core/frame.py", line 4102, in __getitem__
    indexer = self.columns.get_loc(key)
  File "/Users/blueberry/Library/CloudStorage/OneDrive-UniversitätZürichUZH/Studium/FS25/SoComp/SC_RP/rp_implementation/SoComp-FS25/myenv/lib/python3.13/site-packages/pandas/core/indexes/base.py", line 3812, in get_loc
    raise KeyError(key) from err
KeyError: 'cleaned_text'
2025-05-13 18:08:25,145 - __main__ - INFO - Loading data files...
2025-05-13 18:08:25,145 - __main__ - INFO - Loading Reddit posts from: data/raw/reddit_posts_20250506_180725.csv
2025-05-13 18:08:25,146 - __main__ - INFO - Loaded 0 Reddit posts
2025-05-13 18:08:25,147 - __main__ - INFO - Loading Reddit comments from: data/raw/reddit_comments_20250506_180008.csv
2025-05-13 18:08:25,147 - __main__ - INFO - Loaded 6 Reddit comments
2025-05-13 18:08:25,148 - __main__ - INFO - Analyzing sentiment for reddit_comments...
2025-05-13 18:08:25,148 - __main__ - INFO - Applying sentiment analysis to 6 items...
2025-05-13 18:08:25,168 - __main__ - INFO - Sentiment analysis complete
2025-05-13 18:08:25,168 - __main__ - INFO - Computing sentiment statistics...
2025-05-13 18:08:25,169 - __main__ - INFO - Generating visualizations...
2025-05-13 18:08:25,408 - __main__ - INFO - Saved sentiment distribution plot to: data/sentiment/visualizations/sentiment_distribution.png
2025-05-13 18:08:25,549 - __main__ - INFO - Saved sentiment by content length plot to: data/sentiment/visualizations/sentiment_by_length.png
2025-05-13 18:08:25,709 - __main__ - INFO - Saved sentiment by engagement plot to: data/sentiment/visualizations/sentiment_by_engagement.png
2025-05-13 18:08:25,709 - __main__ - INFO - Generating top words visualizations...
2025-05-13 18:08:25,710 - __main__ - ERROR - Error during sentiment analysis: 'cleaned_text'
Traceback (most recent call last):
  File "/Users/blueberry/Library/CloudStorage/OneDrive-UniversitätZürichUZH/Studium/FS25/SoComp/SC_RP/rp_implementation/SoComp-FS25/myenv/lib/python3.13/site-packages/pandas/core/indexes/base.py", line 3805, in get_loc
    return self._engine.get_loc(casted_key)
           ~~~~~~~~~~~~~~~~~~~~^^^^^^^^^^^^
  File "index.pyx", line 167, in pandas._libs.index.IndexEngine.get_loc
  File "index.pyx", line 196, in pandas._libs.index.IndexEngine.get_loc
  File "pandas/_libs/hashtable_class_helper.pxi", line 7081, in pandas._libs.hashtable.PyObjectHashTable.get_item
  File "pandas/_libs/hashtable_class_helper.pxi", line 7089, in pandas._libs.hashtable.PyObjectHashTable.get_item
KeyError: 'cleaned_text'

The above exception was the direct cause of the following exception:

Traceback (most recent call last):
  File "/Users/blueberry/Library/CloudStorage/OneDrive-UniversitätZürichUZH/Studium/FS25/SoComp/SC_RP/rp_implementation/SoComp-FS25/sentiment_analyzer.py", line 1183, in main
    outputs = analyzer.run_complete_analysis(
        reddit_posts_file=args.reddit_posts,
        reddit_comments_file=args.reddit_comments,
        twitter_file=args.twitter
    )
  File "/Users/blueberry/Library/CloudStorage/OneDrive-UniversitätZürichUZH/Studium/FS25/SoComp/SC_RP/rp_implementation/SoComp-FS25/sentiment_analyzer.py", line 1084, in run_complete_analysis
    top_words_visualizations = self.plot_top_words_by_sentiment(analyzed_data, viz_dir)
  File "/Users/blueberry/Library/CloudStorage/OneDrive-UniversitätZürichUZH/Studium/FS25/SoComp/SC_RP/rp_implementation/SoComp-FS25/sentiment_analyzer.py", line 477, in plot_top_words_by_sentiment
    top_words = self.generate_top_words_by_sentiment(df)
  File "/Users/blueberry/Library/CloudStorage/OneDrive-UniversitätZürichUZH/Studium/FS25/SoComp/SC_RP/rp_implementation/SoComp-FS25/sentiment_analyzer.py", line 448, in generate_top_words_by_sentiment
    all_text = ' '.join(category_df[text_column].fillna(''))
                        ~~~~~~~~~~~^^^^^^^^^^^^^
  File "/Users/blueberry/Library/CloudStorage/OneDrive-UniversitätZürichUZH/Studium/FS25/SoComp/SC_RP/rp_implementation/SoComp-FS25/myenv/lib/python3.13/site-packages/pandas/core/frame.py", line 4102, in __getitem__
    indexer = self.columns.get_loc(key)
  File "/Users/blueberry/Library/CloudStorage/OneDrive-UniversitätZürichUZH/Studium/FS25/SoComp/SC_RP/rp_implementation/SoComp-FS25/myenv/lib/python3.13/site-packages/pandas/core/indexes/base.py", line 3812, in get_loc
    raise KeyError(key) from err
KeyError: 'cleaned_text'
2025-05-13 18:08:43,629 - __main__ - INFO - Loading data files...
2025-05-13 18:08:43,630 - __main__ - INFO - Loading Reddit posts from: data/raw/reddit_posts_20250506_180725.csv
2025-05-13 18:08:43,631 - __main__ - INFO - Loaded 0 Reddit posts
2025-05-13 18:08:43,631 - __main__ - INFO - Loading Reddit comments from: data/raw/reddit_comments_20250506_180008.csv
2025-05-13 18:08:43,632 - __main__ - INFO - Loaded 6 Reddit comments
2025-05-13 18:08:43,632 - __main__ - INFO - Loading Twitter data from: /Users/blueberry/Library/CloudStorage/OneDrive-UniversitätZürichUZH/Studium/FS25/SoComp/SC_RP/rp_implementation/twitter_data/twitter_sentiment_data.csv
2025-05-13 18:08:43,684 - __main__ - INFO - Loaded 43943 Twitter posts
2025-05-13 18:08:43,684 - __main__ - INFO - Analyzing sentiment for reddit_comments...
2025-05-13 18:08:43,684 - __main__ - INFO - Applying sentiment analysis to 6 items...
2025-05-13 18:08:43,703 - __main__ - INFO - Sentiment analysis complete
2025-05-13 18:08:43,703 - __main__ - INFO - Analyzing sentiment for twitter...
2025-05-13 18:08:43,703 - __main__ - INFO - Applying sentiment analysis to 43943 items...
2025-05-13 18:08:46,990 - __main__ - INFO - Sentiment analysis complete
2025-05-13 18:08:46,990 - __main__ - INFO - Computing sentiment statistics...
2025-05-13 18:08:47,003 - __main__ - INFO - Generating visualizations...
2025-05-13 18:08:47,244 - __main__ - INFO - Saved sentiment distribution plot to: data/sentiment/visualizations/sentiment_distribution.png
2025-05-13 18:08:47,383 - __main__ - INFO - Saved sentiment by content length plot to: data/sentiment/visualizations/sentiment_by_length.png
2025-05-13 18:08:47,402 - __main__ - WARNING - No engagement metrics found for twitter
2025-05-13 18:08:47,537 - __main__ - INFO - Saved sentiment by engagement plot to: data/sentiment/visualizations/sentiment_by_engagement.png
2025-05-13 18:08:47,538 - __main__ - INFO - Generating top words visualizations...
2025-05-13 18:08:47,538 - __main__ - ERROR - Error during sentiment analysis: 'text_column'
Traceback (most recent call last):
  File "/Users/blueberry/Library/CloudStorage/OneDrive-UniversitätZürichUZH/Studium/FS25/SoComp/SC_RP/rp_implementation/SoComp-FS25/myenv/lib/python3.13/site-packages/pandas/core/indexes/base.py", line 3805, in get_loc
    return self._engine.get_loc(casted_key)
           ~~~~~~~~~~~~~~~~~~~~^^^^^^^^^^^^
  File "index.pyx", line 167, in pandas._libs.index.IndexEngine.get_loc
  File "index.pyx", line 196, in pandas._libs.index.IndexEngine.get_loc
  File "pandas/_libs/hashtable_class_helper.pxi", line 7081, in pandas._libs.hashtable.PyObjectHashTable.get_item
  File "pandas/_libs/hashtable_class_helper.pxi", line 7089, in pandas._libs.hashtable.PyObjectHashTable.get_item
KeyError: 'text_column'

The above exception was the direct cause of the following exception:

Traceback (most recent call last):
  File "/Users/blueberry/Library/CloudStorage/OneDrive-UniversitätZürichUZH/Studium/FS25/SoComp/SC_RP/rp_implementation/SoComp-FS25/sentiment_analyzer.py", line 1183, in main
    outputs = analyzer.run_complete_analysis(
        reddit_posts_file=args.reddit_posts,
        reddit_comments_file=args.reddit_comments,
        twitter_file=args.twitter
    )
  File "/Users/blueberry/Library/CloudStorage/OneDrive-UniversitätZürichUZH/Studium/FS25/SoComp/SC_RP/rp_implementation/SoComp-FS25/sentiment_analyzer.py", line 1084, in run_complete_analysis
    top_words_visualizations = self.plot_top_words_by_sentiment(analyzed_data, viz_dir)
  File "/Users/blueberry/Library/CloudStorage/OneDrive-UniversitätZürichUZH/Studium/FS25/SoComp/SC_RP/rp_implementation/SoComp-FS25/sentiment_analyzer.py", line 477, in plot_top_words_by_sentiment
    top_words = self.generate_top_words_by_sentiment(df)
  File "/Users/blueberry/Library/CloudStorage/OneDrive-UniversitätZürichUZH/Studium/FS25/SoComp/SC_RP/rp_implementation/SoComp-FS25/sentiment_analyzer.py", line 448, in generate_top_words_by_sentiment
    all_text = ' '.join(category_df['text_column'].fillna(''))
                        ~~~~~~~~~~~^^^^^^^^^^^^^^^
  File "/Users/blueberry/Library/CloudStorage/OneDrive-UniversitätZürichUZH/Studium/FS25/SoComp/SC_RP/rp_implementation/SoComp-FS25/myenv/lib/python3.13/site-packages/pandas/core/frame.py", line 4102, in __getitem__
    indexer = self.columns.get_loc(key)
  File "/Users/blueberry/Library/CloudStorage/OneDrive-UniversitätZürichUZH/Studium/FS25/SoComp/SC_RP/rp_implementation/SoComp-FS25/myenv/lib/python3.13/site-packages/pandas/core/indexes/base.py", line 3812, in get_loc
    raise KeyError(key) from err
KeyError: 'text_column'
2025-05-13 18:11:46,256 - __main__ - INFO - Loading data files...
2025-05-13 18:11:46,256 - __main__ - INFO - Loading Reddit posts from: data/raw/reddit_posts_20250506_180725.csv
2025-05-13 18:11:46,257 - __main__ - INFO - Loaded 0 Reddit posts
2025-05-13 18:11:46,257 - __main__ - INFO - Loading Reddit comments from: data/raw/reddit_comments_20250506_180008.csv
2025-05-13 18:11:46,258 - __main__ - INFO - Loaded 6 Reddit comments
2025-05-13 18:11:46,258 - __main__ - INFO - Loading Twitter data from: /Users/blueberry/Library/CloudStorage/OneDrive-UniversitätZürichUZH/Studium/FS25/SoComp/SC_RP/rp_implementation/twitter_data/twitter_sentiment_data.csv
2025-05-13 18:11:46,303 - __main__ - INFO - Loaded 43943 Twitter posts
2025-05-13 18:11:46,303 - __main__ - INFO - Analyzing sentiment for reddit_comments...
2025-05-13 18:11:46,303 - __main__ - INFO - Applying sentiment analysis to 6 items...
2025-05-13 18:11:46,322 - __main__ - INFO - Sentiment analysis complete
2025-05-13 18:11:46,322 - __main__ - INFO - Analyzing sentiment for twitter...
2025-05-13 18:11:46,322 - __main__ - INFO - Applying sentiment analysis to 43943 items...
2025-05-13 18:11:49,669 - __main__ - INFO - Sentiment analysis complete
2025-05-13 18:11:49,670 - __main__ - INFO - Computing sentiment statistics...
2025-05-13 18:11:49,682 - __main__ - INFO - Generating visualizations...
2025-05-13 18:11:49,925 - __main__ - INFO - Saved sentiment distribution plot to: data/sentiment/visualizations/sentiment_distribution.png
2025-05-13 18:11:50,064 - __main__ - INFO - Saved sentiment by content length plot to: data/sentiment/visualizations/sentiment_by_length.png
2025-05-13 18:11:50,083 - __main__ - WARNING - No engagement metrics found for twitter
2025-05-13 18:11:50,225 - __main__ - INFO - Saved sentiment by engagement plot to: data/sentiment/visualizations/sentiment_by_engagement.png
2025-05-13 18:11:50,225 - __main__ - INFO - Generating top words visualizations...
2025-05-13 18:11:50,225 - __main__ - ERROR - Error during sentiment analysis: 'cleaned_text'
Traceback (most recent call last):
  File "/Users/blueberry/Library/CloudStorage/OneDrive-UniversitätZürichUZH/Studium/FS25/SoComp/SC_RP/rp_implementation/SoComp-FS25/myenv/lib/python3.13/site-packages/pandas/core/indexes/base.py", line 3805, in get_loc
    return self._engine.get_loc(casted_key)
           ~~~~~~~~~~~~~~~~~~~~^^^^^^^^^^^^
  File "index.pyx", line 167, in pandas._libs.index.IndexEngine.get_loc
  File "index.pyx", line 196, in pandas._libs.index.IndexEngine.get_loc
  File "pandas/_libs/hashtable_class_helper.pxi", line 7081, in pandas._libs.hashtable.PyObjectHashTable.get_item
  File "pandas/_libs/hashtable_class_helper.pxi", line 7089, in pandas._libs.hashtable.PyObjectHashTable.get_item
KeyError: 'cleaned_text'

The above exception was the direct cause of the following exception:

Traceback (most recent call last):
  File "/Users/blueberry/Library/CloudStorage/OneDrive-UniversitätZürichUZH/Studium/FS25/SoComp/SC_RP/rp_implementation/SoComp-FS25/sentiment_analyzer.py", line 1186, in main
    outputs = analyzer.run_complete_analysis(
        reddit_posts_file=args.reddit_posts,
        reddit_comments_file=args.reddit_comments,
        twitter_file=args.twitter
    )
  File "/Users/blueberry/Library/CloudStorage/OneDrive-UniversitätZürichUZH/Studium/FS25/SoComp/SC_RP/rp_implementation/SoComp-FS25/sentiment_analyzer.py", line 1087, in run_complete_analysis
    top_words_visualizations = self.plot_top_words_by_sentiment(analyzed_data, viz_dir)
  File "/Users/blueberry/Library/CloudStorage/OneDrive-UniversitätZürichUZH/Studium/FS25/SoComp/SC_RP/rp_implementation/SoComp-FS25/sentiment_analyzer.py", line 480, in plot_top_words_by_sentiment
    top_words = self.generate_top_words_by_sentiment(df)
  File "/Users/blueberry/Library/CloudStorage/OneDrive-UniversitätZürichUZH/Studium/FS25/SoComp/SC_RP/rp_implementation/SoComp-FS25/sentiment_analyzer.py", line 451, in generate_top_words_by_sentiment
    all_text = ' '.join(category_df[text_column].fillna(''))
                        ~~~~~~~~~~~^^^^^^^^^^^^^
  File "/Users/blueberry/Library/CloudStorage/OneDrive-UniversitätZürichUZH/Studium/FS25/SoComp/SC_RP/rp_implementation/SoComp-FS25/myenv/lib/python3.13/site-packages/pandas/core/frame.py", line 4102, in __getitem__
    indexer = self.columns.get_loc(key)
  File "/Users/blueberry/Library/CloudStorage/OneDrive-UniversitätZürichUZH/Studium/FS25/SoComp/SC_RP/rp_implementation/SoComp-FS25/myenv/lib/python3.13/site-packages/pandas/core/indexes/base.py", line 3812, in get_loc
    raise KeyError(key) from err
KeyError: 'cleaned_text'
